Workbook

Sheet 知名公園清單
A1: 全台灣知名公園實務母清單｜Google Maps 公園地標為主要核對基準｜共 231 處｜更新日期：2026-07-13
A2: 序號 | B2: 縣市 | C2: 行政區 | D2: 公園名稱 | E2: 類型 | F2: 知名度層級 | G2: DOR收錄優先級 | H2: 代表性理由 | I2: 適合玩法／任務 | J2: 與現有DOR重疊 | K2: 場域性質 | L2: 開放／營運備註 | M2: 官方／主要來源 | N2: 複核狀態 | O2: Google Maps 地標緯度候選（WGS84） | P2: Google Maps 地標經度候選（WGS84） | Q2: Google Maps 核對狀態 | R2: 座標基準／比對方式 | S2: Google Maps 使用說明 | T2: Google Maps 地標搜尋 | U2: 目前座標檢視 | V2: Google Maps 查詢字串 | W2: 場域座標類型
A3: 1 | B3: 臺北市 | C3: 大安區 | D3: 大安森林公園 | E3: 大型城市公園 | F3: S｜全國知名 | G3: P0｜核心 | H3: 城市代表性高、腹地大，兼具休閒、活動與跑步使用。 | I3: 環園探索＋代表地標拍照＋末段加速 | J3: 是｜名稱相同或高度重疊 | K3: 正式公園 | L3: 公共開放為主；活動、施工、夜間照明與局部設施仍須上線前複核。 | M3: https://play4u.gov.taipei/ | N3: Google Maps 主基準工作版；依核對狀態逐筆確認 | O3: 25.03342 | P3: 121.5352 | Q3: A｜Google Maps 單一 POI 候選 | R3: Google Maps 公園地標名稱搜尋為第一順位；現有 WGS84 座標作候選值，既有 DOR／政府資料僅供交叉比對。 | S3: 請開啟 Google Maps 地標搜尋，確認圖釘名稱、縣市與行政區一致；確認後可將圖釘座標作為公園地標座標。 | T3: https://www.google.com/maps/search/?api=1&query=%E5%A4%A7%E5%AE%89%E6%A3%AE%E6%9E%97%E5%85%AC%E5%9C%92%20%E5%A4%A7%E5%AE%89%E5%8D%80%20%E8%87%BA%E5%8C%97%E5%B8%82 | U3: https://www.google.com/maps?q=25.033420,121.535200 | V3: 大安森林公園 大安區 臺北市 | W3: 單一公園 POI
A4: 2 | B4: 臺北市 | C4: 中正區 | D4: 二二八和平公園 | E4: 文化景觀公園 | F4: S｜全國知名 | G4: P0｜核心 | H4: 文化地標、歷史場景與公共綠地結合，適合巡遊任務。 | I4: 文化地標巡遊＋拍照＋簡易問答 | J4: 待比對 | K4: 正式公園 | L4: 公共開放為主；活動、施工、夜間照明與局部設施仍須上線前複核。 | M4: https://play4u.gov.taipei/ | N4: Google Maps 主基準工作版；依核對狀態逐筆確認 | O4: 25.04044 | P4: 121.51417 | Q4: A｜Google Maps 單一 POI 候選 | R4: Google Maps 公園地標名稱搜尋為第一順位；現有 WGS84 座標作候選值，既有 DOR／政府資料僅供交叉比對。 | S4: 請開啟 Google Maps 地標搜尋，確認圖釘名稱、縣市與行政區一致；確認後可將圖釘座標作為公園地標座標。 | T4: https://www.google.com/maps/search/?api=1&query=%E4%BA%8C%E4%BA%8C%E5%85%AB%E5%92%8C%E5%B9%B3%E5%85%AC%E5%9C%92%20%E4%B8%AD%E6%AD%A3%E5%8D%80%20%E8%87%BA%E5%8C%97%E5%B8%82 | U4: https://www.google.com/maps?q=25.040440,121.514170 | V4: 二二八和平公園 中正區 臺北市 | W4: 單一公園 POI
A5: 3 | B5: 臺北市 | C5: 士林區 | D5: 士林官邸公園 | E5: 文化景觀公園 | F5: S｜全國知名 | G5: P0｜核心 | H5: 文化地標、歷史場景與公共綠地結合，適合巡遊任務。 | I5: 文化地標巡遊＋拍照＋簡易問答 | J5: 待比對 | K5: 正式公園 | L5: 公共開放為主；活動、施工、夜間照明與局部設施仍須上線前複核。 | M5: https://play4u.gov.taipei/ | N5: Google Maps 主基準工作版；依核對狀態逐筆確認 | O5: 25.0949 | P5: 121.53015 | Q5: A｜Google Maps 單一 POI 候選 | R5: Google Maps 公園地標名稱搜尋為第一順位；現有 WGS84 座標作候選值，既有 DOR／政府資料僅供交叉比對。 | S5: 請開啟 Google Maps 地標搜尋，確認圖釘名稱、縣市與行政區一致；確認後可將圖釘座標作為公園地標座標。 | T5: https://www.google.com/maps/search/?api=1&query=%E5%A3%AB%E6%9E%97%E5%AE%98%E9%82%B8%E5%85%AC%E5%9C%92%20%E5%A3%AB%E6%9E%97%E5%8D%80%20%E8%87%BA%E5%8C%97%E5%B8%82 | U5: https://www.google.com/maps?q=25.094900,121.530150 | V5: 士林官邸公園 士林區 臺北市 | W5: 單一公園 POI
A6: 4 | B6: 臺北市 | C6: 北投區 | D6: 北投公園 | E6: 文化景觀公園 | F6: A｜縣市代表 | G6: P0｜核心 | H6: 文化地標、歷史場景與公共綠地結合，適合巡遊任務。 | I6: 文化地標巡遊＋拍照＋簡易問答 | J6: 待比對 | K6: 正式公園 | L6: 公共開放為主；活動、施工、夜間照明與局部設施仍須上線前複核。 | M6: https://play4u.gov.taipei/ | N6: Google Maps 主基準工作版；依核對狀態逐筆確認 | O6: 25.13656 | P6: 121.50473 | Q6: A｜Google Maps 單一 POI 候選 | R6: Google Maps 公園地標名稱搜尋為第一順位；現有 WGS84 座標作候選值，既有 DOR／政府資料僅供交叉比對。 | S6: 請開啟 Google Maps 地標搜尋，確認圖釘名稱、縣市與行政區一致；確認後可將圖釘座標作為公園地標座標。 | T6: https://www.google.com/maps/search/?api=1&query=%E5%8C%97%E6%8A%95%E5%85%AC%E5%9C%92%20%E5%8C%97%E6%8A%95%E5%8D%80%20%E8%87%BA%E5%8C%97%E5%B8%82 | U6: https://www.google.com/maps?q=25.136560,121.504730 | V6: 北投公園 北投區 臺北市 | W6: 單一公園 POI
A7: 5 | B7: 臺北市 | C7: 北投區 | D7: 陽明公園 | E7: 山坡森林公園 | F7: A｜縣市代表 | G7: P1｜擴充 | H7: 林蔭、坡度或視野明顯，適合爬升與地形任務。 | I7: 坡跑／階梯＋爬升高度＋觀景點 | J7: 待比對 | K7: 正式公園 | L7: 公共開放為主；活動、施工、夜間照明與局部設施仍須上線前複核。 | M7: https://play4u.gov.taipei/ | N7: Google Maps 主基準工作版；依核對狀態逐筆確認 | O7: 25.15787 | P7: 121.54252 | Q7: A｜Google Maps 單一 POI 候選 | R7: Google Maps 公園地標名稱搜尋為第一順位；現有 WGS84 座標作候選值，既有 DOR／政府資料僅供交叉比對。 | S7: 請開啟 Google Maps 地標搜尋，確認圖釘名稱、縣市與行政區一致；確認後可將圖釘座標作為公園地標座標。 | T7: https://www.google.com/maps/search/?api=1&query=%E9%99%BD%E6%98%8E%E5%85%AC%E5%9C%92%20%E5%8C%97%E6%8A%95%E5%8D%80%20%E8%87%BA%E5%8C%97%E5%B8%82 | U7: https://www.google.com/maps?q=25.157870,121.542520 | V7: 陽明公園 北投區 臺北市 | W7: 單一公園 POI
A8: 6 | B8: 臺北市 | C8: 內湖區 | D8: 大湖公園 | E8: 城市公園 | F8: A｜縣市代表 | G8: P0｜核心 | H8: 生活圈辨識度高，適合日常探索與環園任務。 | I8: 環園一圈＋指定設施／地標打卡 | J8: 是｜名稱相同或高度重疊 | K8: 正式公園 | L8: 公共開放為主；活動、施工、夜間照明與局部設施仍須上線前複核。 | M8: https://play4u.gov.taipei/ | N8: Google Maps 主基準工作版；依核對狀態逐筆確認 | O8: 25.0837 | P8: 121.602 | Q8: A｜Google Maps 單一 POI 候選 | R8: Google Maps 公園地標名稱搜尋為第一順位；現有 WGS84 座標作候選值，既有 DOR／政府資料僅供交叉比對。 | S8: 請開啟 Google Maps 地標搜尋，確認圖釘名稱、縣市與行政區一致；確認後可將圖釘座標作為公園地標座標。 | T8: https://www.google.com/maps/search/?api=1&query=%E5%A4%A7%E6%B9%96%E5%85%AC%E5%9C%92%20%E5%85%A7%E6%B9%96%E5%8D%80%20%E8%87%BA%E5%8C%97%E5%B8%82 | U8: https://www.google.com/maps?q=25.083700,121.602000 | V8: 大湖公園 內湖區 臺北市 | W8: 單一公園 POI
A9: 7 | B9: 臺北市 | C9: 內湖區 | D9: 碧湖公園 | E9: 城市公園 | F9: A｜縣市代表 | G9: P1｜擴充 | H9: 生活圈辨識度高，適合日常探索與環園任務。 | I9: 環園一圈＋指定設施／地標打卡 | J9: 待比對 | K9: 正式公園 | L9: 公共開放為主；活動、施工、夜間照明與局部設施仍須上線前複核。 | M9: https://play4u.gov.taipei/ | N9: Google Maps 主基準工作版；依核對狀態逐筆確認 | O9: 25.08219 | P9: 121.58429 | Q9: A｜Google Maps 單一 POI 候選 | R9: Google Maps 公園地標名稱搜尋為第一順位；現有 WGS84 座標作候選值，既有 DOR／政府資料僅供交叉比對。 | S9: 請開啟 Google Maps 地標搜尋，確認圖釘名稱、縣市與行政區一致；確認後可將圖釘座標作為公園地標座標。 | T9: https://www.google.com/maps/search/?api=1&query=%E7%A2%A7%E6%B9%96%E5%85%AC%E5%9C%92%20%E5%85%A7%E6%B9%96%E5%8D%80%20%E8%87%BA%E5%8C%97%E5%B8%82 | U9: https://www.google.com/maps?q=25.082190,121.584290 | V9: 碧湖公園 內湖區 臺北市 | W9: 單一公園 POI
A10: 8 | B10: 臺北市 | C10: 南港區 | D10: 南港公園 | E10: 城市公園 | F10: A｜縣市代表 | G10: P0｜核心 | H10: 生活圈辨識度高，適合日常探索與環園任務。 | I10: 環園一圈＋指定設施／地標打卡 | J10: 是｜名稱相同或高度重疊 | K10: 正式公園 | L10: 公共開放為主；活動、施工、夜間照明與局部設施仍須上線前複核。 | M10: https://play4u.gov.taipei/ | N10: Google Maps 主基準工作版；依核對狀態逐筆確認 | O10: 25.0394 | P10: 121.5905 | Q10: A｜Google Maps 單一 POI 候選 | R10: Google Maps 公園地標名稱搜尋為第一順位；現有 WGS84 座標作候選值，既有 DOR／政府資料僅供交叉比對。 | S10: 請開啟 Google Maps 地標搜尋，確認圖釘名稱、縣市與行政區一致；確認後可將圖釘座標作為公園地標座標。 | T10: https://www.google.com/maps/search/?api=1&query=%E5%8D%97%E6%B8%AF%E5%85%AC%E5%9C%92%20%E5%8D%97%E6%B8%AF%E5%8D%80%20%E8%87%BA%E5%8C%97%E5%B8%82 | U10: https://www.google.com/maps?q=25.039400,121.590500 | V10: 南港公園 南港區 臺北市 | W10: 單一公園 POI
A11: 9 | B11: 臺北市 | C11: 萬華區 | D11: 青年公園 | E11: 運動公園 | F11: A｜縣市代表 | G11: P0｜核心 | H11: 區域運動核心，適合圈數、配速與體能任務。 | I11: 圈數任務＋穩定配速＋體能挑戰 | J11: 是｜名稱相同或高度重疊 | K11: 正式公園 | L11: 公共開放為主；活動、施工、夜間照明與局部設施仍須上線前複核。 | M11: https://play4u.gov.taipei/ | N11: Google Maps 主基準工作版；依核對狀態逐筆確認 | O11: 25.0227 | P11: 121.5052 | Q11: A｜Google Maps 單一 POI 候選 | R11: Google Maps 公園地標名稱搜尋為第一順位；現有 WGS84 座標作候選值，既有 DOR／政府資料僅供交叉比對。 | S11: 請開啟 Google Maps 地標搜尋，確認圖釘名稱、縣市與行政區一致；確認後可將圖釘座標作為公園地標座標。 | T11: https://www.google.com/maps/search/?api=1&query=%E9%9D%92%E5%B9%B4%E5%85%AC%E5%9C%92%20%E8%90%AC%E8%8F%AF%E5%8D%80%20%E8%87%BA%E5%8C%97%E5%B8%82 | U11: https://www.google.com/maps?q=25.022700,121.505200 | V11: 青年公園 萬華區 臺北市 | W11: 單一公園 POI
A12: 10 | B12: 臺北市 | C12: 中山區 | D12: 花博公園（圓山／美術／新生園區） | E12: 大型城市公園 | F12: S｜全國知名 | G12: P0｜核心 | H12: 城市代表性高、腹地大，兼具休閒、活動與跑步使用。 | I12: 環園探索＋代表地標拍照＋末段加速 | J12: 是｜名稱相同或高度重疊 | K12: 正式公園 | L12: 公共開放為主；活動、施工、夜間照明與局部設施仍須上線前複核。 | M12: https://play4u.gov.taipei/ | N12: Google Maps 主基準工作版；依核對狀態逐筆確認 | O12: 25.0691 | P12: 121.5323 | Q12: C｜Google Maps 需人工選定主地標 | R12: Google Maps 公園地標名稱搜尋為第一順位；現有 WGS84 座標作候選值，既有 DOR／政府資料僅供交叉比對。 | S12: 名稱包含多園區或複合場域，Google Maps 可能顯示多個圖釘；須先拆分或指定主園區後，再確定唯一座標。 | T12: https://www.google.com/maps/search/?api=1&query=%E8%8A%B1%E5%8D%9A%E5%85%AC%E5%9C%92%EF%BC%88%E5%9C%93%E5%B1%B1%EF%BC%8F%E7%BE%8E%E8%A1%93%EF%BC%8F%E6%96%B0%E7%94%9F%E5%9C%92%E5%8D%80%EF%BC%89%20%E4%B8%AD%E5%B1%B1%E5%8D%80%20%E8%87%BA%E5%8C%97%E5%B8%82 | U12: https://www.google.com/maps?q=25.069100,121.532300 | V12: 花博公園（圓山／美術／新生園區） 中山區 臺北市 | W12: 複合／多園區地標
A13: 11 | B13: 臺北市 | C13: 中山區 | D13: 榮星花園公園 | E13: 城市公園 | F13: A｜縣市代表 | G13: P1｜擴充 | H13: 生活圈辨識度高，適合日常探索與環園任務。 | I13: 環園一圈＋指定設施／地標打卡 | J13: 待比對 | K13: 正式公園 | L13: 公共開放為主；活動、施工、夜間照明與局部設施仍須上線前複核。 | M13: https://play4u.gov.taipei/ | N13: Google Maps 主基準工作版；依核對狀態逐筆確認 | O13: 25.06265 | P13: 121.5405 | Q13: A｜Google Maps 單一 POI 候選 | R13: Google Maps 公園地標名稱搜尋為第一順位；現有 WGS84 座標作候選值，既有 DOR／政府資料僅供交叉比對。 | S13: 請開啟 Google Maps 地標搜尋，確認圖釘名稱、縣市與行政區一致；確認後可將圖釘座標作為公園地標座標。 | T13: https://www.google.com/maps/search/?api=1&query=%E6%A6%AE%E6%98%9F%E8%8A%B1%E5%9C%92%E5%85%AC%E5%9C%92%20%E4%B8%AD%E5%B1%B1%E5%8D%80%20%E8%87%BA%E5%8C%97%E5%B8%82 | U13: https://www.google.com/maps?q=25.062650,121.540500 | V13: 榮星花園公園 中山區 臺北市 | W13: 單一公園 POI
A14: 12 | B14: 臺北市 | C14: 士林區 | D14: 天母運動公園 | E14: 運動公園 | F14: A｜縣市代表 | G14: P1｜擴充 | H14: 區域運動核心，適合圈數、配速與體能任務。 | I14: 圈數任務＋穩定配速＋體能挑戰 | J14: 是｜名稱相同或高度重疊 | K14: 正式公園 | L14: 公共開放為主；活動、施工、夜間照明與局部設施仍須上線前複核。 | M14: https://play4u.gov.taipei/ | N14: Google Maps 主基準工作版；依核對狀態逐筆確認 | O14: 25.1158 | P14: 121.532 | Q14: A｜Google Maps 單一 POI 候選 | R14: Google Maps 公園地標名稱搜尋為第一順位；現有 WGS84 座標作候選值，既有 DOR／政府資料僅供交叉比對。 | S14: 請開啟 Google Maps 地標搜尋，確認圖釘名稱、縣市與行政區一致；確認後可將圖釘座標作為公園地標座標。 | T14: https://www.google.com/maps/search/?api=1&query=%E5%A4%A9%E6%AF%8D%E9%81%8B%E5%8B%95%E5%85%AC%E5%9C%92%20%E5%A3%AB%E6%9E%97%E5%8D%80%20%E8%87%BA%E5%8C%97%E5%B8%82 | U14: https://www.google.com/maps?q=25.115800,121.532000 | V14: 天母運動公園 士林區 臺北市 | W14: 單一公園 POI
... A233: 231 | B233: 連江縣 | C233: 南竿鄉 | D233: 馬祖民俗文物館園區 | E233: 文化景觀公園 | F233: A｜縣市代表 | G233: P1｜擴充 | H233: 文化地標、歷史場景與公共綠地結合，適合巡遊任務。 | I233: 文化地標巡遊＋拍照＋簡易問答 | J233: 待比對 | K233: 公園型公共園區 | L233: 納入廣義公園清單；可能有開放時間、門票或場域管理規則，需另外複核。 | M233: https://www.matsu-nsa.gov.tw/ | N233: Google Maps 主基準工作版；依核對狀態逐筆確認 | O233: 26.1569 | P233: 119.9515 | Q233: C｜Google Maps 優先複核 | R233: Google Maps 公園地標名稱搜尋為第一順位；現有 WGS84 座標作候選值，既有 DOR／政府資料僅供交叉比對。 | S233: 屬大型景區或公共園區，Google Maps 圖釘可能落在遊客中心、入口或核心設施；需依產品用途確認代表點。 | T233: https://www.google.com/maps/search/?api=1&query=%E9%A6%AC%E7%A5%96%E6%B0%91%E4%BF%97%E6%96%87%E7%89%A9%E9%A4%A8%E5%9C%92%E5%8D%80%20%E5%8D%97%E7%AB%BF%E9%84%89%20%E9%80%A3%E6%B1%9F%E7%B8%A3 | U233: https://www.google.com/maps?q=26.156900,119.951500 | V233: 馬祖民俗文物館園區 南竿鄉 連江縣 | W233: 景區／公共園區 POI

Sheet 縣市摘要
A1: 全台灣知名公園｜縣市分布與分級摘要
A2: 縣市 | B2: 總數 | C2: S｜全國知名 | D2: A｜縣市代表 | E2: B｜區域熱門 | F2: P0｜核心 | G2: P1｜擴充 | H2: P2｜候補
A3: 臺北市 | B3: =COUNTIF(知名公園清單!$B$3:$B$233,A3) -> 18 | C3: =COUNTIFS(知名公園清單!$B$3:$B$233,A3,知名公園清單!$F$3:$F$233,"S｜全國知名") -> 5 | D3: =COUNTIFS(知名公園清單!$B$3:$B$233,A3,知名公園清單!$F$3:$F$233,"A｜縣市代表") -> 13 | E3: =COUNTIFS(知名公園清單!$B$3:$B$233,A3,知名公園清單!$F$3:$F$233,"B｜區域熱門") -> 0 | F3: =COUNTIFS(知名公園清單!$B$3:$B$233,A3,知名公園清單!$G$3:$G$233,"P0｜核心") -> 9 | G3: =COUNTIFS(知名公園清單!$B$3:$B$233,A3,知名公園清單!$G$3:$G$233,"P1｜擴充") -> 9 | H3: =COUNTIFS(知名公園清單!$B$3:$B$233,A3,知名公園清單!$G$3:$G$233,"P2｜候補") -> 0
A4: 新北市 | B4: =COUNTIF(知名公園清單!$B$3:$B$233,A4) -> 18 | C4: =COUNTIFS(知名公園清單!$B$3:$B$233,A4,知名公園清單!$F$3:$F$233,"S｜全國知名") -> 3 | D4: =COUNTIFS(知名公園清單!$B$3:$B$233,A4,知名公園清單!$F$3:$F$233,"A｜縣市代表") -> 13 | E4: =COUNTIFS(知名公園清單!$B$3:$B$233,A4,知名公園清單!$F$3:$F$233,"B｜區域熱門") -> 2 | F4: =COUNTIFS(知名公園清單!$B$3:$B$233,A4,知名公園清單!$G$3:$G$233,"P0｜核心") -> 6 | G4: =COUNTIFS(知名公園清單!$B$3:$B$233,A4,知名公園清單!$G$3:$G$233,"P1｜擴充") -> 11 | H4: =COUNTIFS(知名公園清單!$B$3:$B$233,A4,知名公園清單!$G$3:$G$233,"P2｜候補") -> 1
A5: 基隆市 | B5: =COUNTIF(知名公園清單!$B$3:$B$233,A5) -> 7 | C5: =COUNTIFS(知名公園清單!$B$3:$B$233,A5,知名公園清單!$F$3:$F$233,"S｜全國知名") -> 2 | D5: =COUNTIFS(知名公園清單!$B$3:$B$233,A5,知名公園清單!$F$3:$F$233,"A｜縣市代表") -> 5 | E5: =COUNTIFS(知名公園清單!$B$3:$B$233,A5,知名公園清單!$F$3:$F$233,"B｜區域熱門") -> 0 | F5: =COUNTIFS(知名公園清單!$B$3:$B$233,A5,知名公園清單!$G$3:$G$233,"P0｜核心") -> 3 | G5: =COUNTIFS(知名公園清單!$B$3:$B$233,A5,知名公園清單!$G$3:$G$233,"P1｜擴充") -> 4 | H5: =COUNTIFS(知名公園清單!$B$3:$B$233,A5,知名公園清單!$G$3:$G$233,"P2｜候補") -> 0
A6: 桃園市 | B6: =COUNTIF(知名公園清單!$B$3:$B$233,A6) -> 16 | C6: =COUNTIFS(知名公園清單!$B$3:$B$233,A6,知名公園清單!$F$3:$F$233,"S｜全國知名") -> 3 | D6: =COUNTIFS(知名公園清單!$B$3:$B$233,A6,知名公園清單!$F$3:$F$233,"A｜縣市代表") -> 11 | E6: =COUNTIFS(知名公園清單!$B$3:$B$233,A6,知名公園清單!$F$3:$F$233,"B｜區域熱門") -> 2 | F6: =COUNTIFS(知名公園清單!$B$3:$B$233,A6,知名公園清單!$G$3:$G$233,"P0｜核心") -> 5 | G6: =COUNTIFS(知名公園清單!$B$3:$B$233,A6,知名公園清單!$G$3:$G$233,"P1｜擴充") -> 9 | H6: =COUNTIFS(知名公園清單!$B$3:$B$233,A6,知名公園清單!$G$3:$G$233,"P2｜候補") -> 2
A7: 新竹市 | B7: =COUNTIF(知名公園清單!$B$3:$B$233,A7) -> 10 | C7: =COUNTIFS(知名公園清單!$B$3:$B$233,A7,知名公園清單!$F$3:$F$233,"S｜全國知名") -> 3 | D7: =COUNTIFS(知名公園清單!$B$3:$B$233,A7,知名公園清單!$F$3:$F$233,"A｜縣市代表") -> 5 | E7: =COUNTIFS(知名公園清單!$B$3:$B$233,A7,知名公園清單!$F$3:$F$233,"B｜區域熱門") -> 2 | F7: =COUNTIFS(知名公園清單!$B$3:$B$233,A7,知名公園清單!$G$3:$G$233,"P0｜核心") -> 4 | G7: =COUNTIFS(知名公園清單!$B$3:$B$233,A7,知名公園清單!$G$3:$G$233,"P1｜擴充") -> 4 | H7: =COUNTIFS(知名公園清單!$B$3:$B$233,A7,知名公園清單!$G$3:$G$233,"P2｜候補") -> 2
A8: 新竹縣 | B8: =COUNTIF(知名公園清單!$B$3:$B$233,A8) -> 8 | C8: =COUNTIFS(知名公園清單!$B$3:$B$233,A8,知名公園清單!$F$3:$F$233,"S｜全國知名") -> 0 | D8: =COUNTIFS(知名公園清單!$B$3:$B$233,A8,知名公園清單!$F$3:$F$233,"A｜縣市代表") -> 6 | E8: =COUNTIFS(知名公園清單!$B$3:$B$233,A8,知名公園清單!$F$3:$F$233,"B｜區域熱門") -> 2 | F8: =COUNTIFS(知名公園清單!$B$3:$B$233,A8,知名公園清單!$G$3:$G$233,"P0｜核心") -> 2 | G8: =COUNTIFS(知名公園清單!$B$3:$B$233,A8,知名公園清單!$G$3:$G$233,"P1｜擴充") -> 4 | H8: =COUNTIFS(知名公園清單!$B$3:$B$233,A8,知名公園清單!$G$3:$G$233,"P2｜候補") -> 2
A9: 苗栗縣 | B9: =COUNTIF(知名公園清單!$B$3:$B$233,A9) -> 9 | C9: =COUNTIFS(知名公園清單!$B$3:$B$233,A9,知名公園清單!$F$3:$F$233,"S｜全國知名") -> 0 | D9: =COUNTIFS(知名公園清單!$B$3:$B$233,A9,知名公園清單!$F$3:$F$233,"A｜縣市代表") -> 8 | E9: =COUNTIFS(知名公園清單!$B$3:$B$233,A9,知名公園清單!$F$3:$F$233,"B｜區域熱門") -> 1 | F9: =COUNTIFS(知名公園清單!$B$3:$B$233,A9,知名公園清單!$G$3:$G$233,"P0｜核心") -> 2 | G9: =COUNTIFS(知名公園清單!$B$3:$B$233,A9,知名公園清單!$G$3:$G$233,"P1｜擴充") -> 6 | H9: =COUNTIFS(知名公園清單!$B$3:$B$233,A9,知名公園清單!$G$3:$G$233,"P2｜候補") -> 1
A10: 臺中市 | B10: =COUNTIF(知名公園清單!$B$3:$B$233,A10) -> 16 | C10: =COUNTIFS(知名公園清單!$B$3:$B$233,A10,知名公園清單!$F$3:$F$233,"S｜全國知名") -> 6 | D10: =COUNTIFS(知名公園清單!$B$3:$B$233,A10,知名公園清單!$F$3:$F$233,"A｜縣市代表") -> 9 | E10: =COUNTIFS(知名公園清單!$B$3:$B$233,A10,知名公園清單!$F$3:$F$233,"B｜區域熱門") -> 1 | F10: =COUNTIFS(知名公園清單!$B$3:$B$233,A10,知名公園清單!$G$3:$G$233,"P0｜核心") -> 6 | G10: =COUNTIFS(知名公園清單!$B$3:$B$233,A10,知名公園清單!$G$3:$G$233,"P1｜擴充") -> 9 | H10: =COUNTIFS(知名公園清單!$B$3:$B$233,A10,知名公園清單!$G$3:$G$233,"P2｜候補") -> 1
A11: 彰化縣 | B11: =COUNTIF(知名公園清單!$B$3:$B$233,A11) -> 9 | C11: =COUNTIFS(知名公園清單!$B$3:$B$233,A11,知名公園清單!$F$3:$F$233,"S｜全國知名") -> 2 | D11: =COUNTIFS(知名公園清單!$B$3:$B$233,A11,知名公園清單!$F$3:$F$233,"A｜縣市代表") -> 6 | E11: =COUNTIFS(知名公園清單!$B$3:$B$233,A11,知名公園清單!$F$3:$F$233,"B｜區域熱門") -> 1 | F11: =COUNTIFS(知名公園清單!$B$3:$B$233,A11,知名公園清單!$G$3:$G$233,"P0｜核心") -> 3 | G11: =COUNTIFS(知名公園清單!$B$3:$B$233,A11,知名公園清單!$G$3:$G$233,"P1｜擴充") -> 5 | H11: =COUNTIFS(知名公園清單!$B$3:$B$233,A11,知名公園清單!$G$3:$G$233,"P2｜候補") -> 1
A12: 南投縣 | B12: =COUNTIF(知名公園清單!$B$3:$B$233,A12) -> 8 | C12: =COUNTIFS(知名公園清單!$B$3:$B$233,A12,知名公園清單!$F$3:$F$233,"S｜全國知名") -> 0 | D12: =COUNTIFS(知名公園清單!$B$3:$B$233,A12,知名公園清單!$F$3:$F$233,"A｜縣市代表") -> 6 | E12: =COUNTIFS(知名公園清單!$B$3:$B$233,A12,知名公園清單!$F$3:$F$233,"B｜區域熱門") -> 2 | F12: =COUNTIFS(知名公園清單!$B$3:$B$233,A12,知名公園清單!$G$3:$G$233,"P0｜核心") -> 1 | G12: =COUNTIFS(知名公園清單!$B$3:$B$233,A12,知名公園清單!$G$3:$G$233,"P1｜擴充") -> 5 | H12: =COUNTIFS(知名公園清單!$B$3:$B$233,A12,知名公園清單!$G$3:$G$233,"P2｜候補") -> 2
A13: 雲林縣 | B13: =COUNTIF(知名公園清單!$B$3:$B$233,A13) -> 9 | C13: =COUNTIFS(知名公園清單!$B$3:$B$233,A13,知名公園清單!$F$3:$F$233,"S｜全國知名") -> 1 | D13: =COUNTIFS(知名公園清單!$B$3:$B$233,A13,知名公園清單!$F$3:$F$233,"A｜縣市代表") -> 6 | E13: =COUNTIFS(知名公園清單!$B$3:$B$233,A13,知名公園清單!$F$3:$F$233,"B｜區域熱門") -> 2 | F13: =COUNTIFS(知名公園清單!$B$3:$B$233,A13,知名公園清單!$G$3:$G$233,"P0｜核心") -> 2 | G13: =COUNTIFS(知名公園清單!$B$3:$B$233,A13,知名公園清單!$G$3:$G$233,"P1｜擴充") -> 5 | H13: =COUNTIFS(知名公園清單!$B$3:$B$233,A13,知名公園清單!$G$3:$G$233,"P2｜候補") -> 2
A14: 嘉義市 | B14: =COUNTIF(知名公園清單!$B$3:$B$233,A14) -> 7 | C14: =COUNTIFS(知名公園清單!$B$3:$B$233,A14,知名公園清單!$F$3:$F$233,"S｜全國知名") -> 1 | D14: =COUNTIFS(知名公園清單!$B$3:$B$233,A14,知名公園清單!$F$3:$F$233,"A｜縣市代表") -> 5 | E14: =COUNTIFS(知名公園清單!$B$3:$B$233,A14,知名公園清單!$F$3:$F$233,"B｜區域熱門") -> 1 | F14: =COUNTIFS(知名公園清單!$B$3:$B$233,A14,知名公園清單!$G$3:$G$233,"P0｜核心") -> 2 | G14: =COUNTIFS(知名公園清單!$B$3:$B$233,A14,知名公園清單!$G$3:$G$233,"P1｜擴充") -> 4 | H14: =COUNTIFS(知名公園清單!$B$3:$B$233,A14,知名公園清單!$G$3:$G$233,"P2｜候補") -> 1
... A23: 金門縣 | B23: =COUNTIF(知名公園清單!$B$3:$B$233,A23) -> 7 | C23: =COUNTIFS(知名公園清單!$B$3:$B$233,A23,知名公園清單!$F$3:$F$233,"S｜全國知名") -> 3 | D23: =COUNTIFS(知名公園清單!$B$3:$B$233,A23,知名公園清單!$F$3:$F$233,"A｜縣市代表") -> 4 | E23: =COUNTIFS(知名公園清單!$B$3:$B$233,A23,知名公園清單!$F$3:$F$233,"B｜區域熱門") -> 0 | F23: =COUNTIFS(知名公園清單!$B$3:$B$233,A23,知名公園清單!$G$3:$G$233,"P0｜核心") -> 4 | G23: =COUNTIFS(知名公園清單!$B$3:$B$233,A23,知名公園清單!$G$3:$G$233,"P1｜擴充") -> 3 | H23: =COUNTIFS(知名公園清單!$B$3:$B$233,A23,知名公園清單!$G$3:$G$233,"P2｜候補") -> 0
A24: 連江縣 | B24: =COUNTIF(知名公園清單!$B$3:$B$233,A24) -> 4 | C24: =COUNTIFS(知名公園清單!$B$3:$B$233,A24,知名公園清單!$F$3:$F$233,"S｜全國知名") -> 2 | D24: =COUNTIFS(知名公園清單!$B$3:$B$233,A24,知名公園清單!$F$3:$F$233,"A｜縣市代表") -> 2 | E24: =COUNTIFS(知名公園清單!$B$3:$B$233,A24,知名公園清單!$F$3:$F$233,"B｜區域熱門") -> 0 | F24: =COUNTIFS(知名公園清單!$B$3:$B$233,A24,知名公園清單!$G$3:$G$233,"P0｜核心") -> 2 | G24: =COUNTIFS(知名公園清單!$B$3:$B$233,A24,知名公園清單!$G$3:$G$233,"P1｜擴充") -> 2 | H24: =COUNTIFS(知名公園清單!$B$3:$B$233,A24,知名公園清單!$G$3:$G$233,"P2｜候補") -> 0 | J24: Google Maps 核對狀態摘要
A25: 合計 | B25: =SUM(B3:B24) -> 231 | C25: =SUM(C3:C24) -> 70 | D25: =SUM(D3:D24) -> 140 | E25: =SUM(E3:E24) -> 21 | F25: =SUM(F3:F24) -> 95 | G25: =SUM(G3:G24) -> 116 | H25: =SUM(H3:H24) -> 20 | J25: 層級 | K25: 筆數 | L25: 占比 | M25: 使用說明
J26: A｜單一 POI 候選 | K26: =COUNTIF(知名公園清單!$Q$3:$Q$233,"A｜Google Maps 單一 POI 候選") -> 50 | L26: =K26/$B$25 -> 0.21645022 | M26: 先點開 Google Maps 名稱搜尋抽查，再作正式座標。
J27: B｜名稱搜尋待核對 | K27: =COUNTIF(知名公園清單!$Q$3:$Q$233,"B｜Google Maps 名稱搜尋待核對") -> 92 | L27: =K27/$B$25 -> 0.3982684 | M27: 需確認 Google Maps 圖釘名稱、行政區及位置一致。
J28: C｜人工選點／優先複核 | K28: =COUNTIF(知名公園清單!$Q$3:$Q$233,"C｜Google Maps 需人工選定主地標")+COUNTIF(知名公園清單!$Q$3:$Q$233,"C｜Google Maps 優先複核") -> 89 | L28: =K28/$B$25 -> 0.38528139 | M28: 複合、線性或原始可信度較低，禁止未核對直接作 GPS 判定。

Sheet 篩選原則
A1: 篩選原則、分級定義與使用注意事項
A2: 項目 | B2: 定義／處理方式
A3: 本清單定位 | B3: 供 DOR 城市探索、內容企劃與後續座標建檔使用的「實務母清單」，不是政府法定公園總名冊。
A4: 納入標準 | B4: 城市／縣市代表性、觀光辨識度、規模或活動使用度、跑步／親子／休閒熱度，至少符合其中一項。
A5: 排除標準 | B5: 鄰里小公園、口袋公園、純私人園區、私人遊樂園、國家公園、森林遊樂區，以及缺乏公共辨識度的冷門場地。
A6: 廣義場域 | B6: 離島或正式公園較少的縣市，保留少量具公園功能的公共景觀、文化或生態園區，並在「場域性質」標明。
A7: S｜全國知名 | B7: 跨縣市旅遊辨識度高，或屬全國性地標／大型都會公園。
A8: A｜縣市代表 | B8: 縣市居民與遊客普遍知道，具明顯城市代表性或主題特色。
A9: B｜區域熱門 | B9: 在行政區或生活圈內具熱度，但全國辨識度相對有限。
A10: P0｜核心 | B10: 建議優先建立座標、任務與關主設定；可作為縣市章節主點。
A11: P1｜擴充 | B11: 適合補足行政區、玩法與主題多樣性。
A12: P2｜候補 | B12: 保留於母清單；待資料量、營運需求或在地熱度驗證後再上線。
A13: 現有DOR重疊 | B13: 只標示本次能從既有工作簿確認的明顯同名／高度重疊項目；仍建議以正式名稱與座標再次去重。
... A20: Google Places 資料注意 | B20: 若需大量、自動化取得 Google Places 的正式地標資料，應使用 Google Places API 並依官方授權、API 金鑰與計費規範執行。官方文件：https://developers.google.com/maps/documentation/places/web-service/overview

Sheet Google Maps複核清單
A1: Google Maps 優先複核清單｜共 184 處｜包含 B／C 狀態及非單一公園 POI 場域
A2: 序號 | B2: 縣市 | C2: 行政區 | D2: 公園名稱 | E2: 候選緯度 | F2: 候選經度 | G2: Google Maps 核對狀態 | H2: 場域座標類型 | I2: Google Maps 地標搜尋 | J2: 目前座標檢視 | K2: DOR優先級
A3: 10 | B3: 臺北市 | C3: 中山區 | D3: 花博公園（圓山／美術／新生園區） | E3: 25.0691 | F3: 121.5323 | G3: C｜Google Maps 需人工選定主地標 | H3: 複合／多園區地標 | I3: https://www.google.com/maps/search/?api=1&query=%E8%8A%B1%E5%8D%9A%E5%85%AC%E5%9C%92%EF%BC%88%E5%9C%93%E5%B1%B1%EF%BC%8F%E7%BE%8E%E8%A1%93%EF%BC%8F%E6%96%B0%E7%94%9F%E5%9C%92%E5%8D%80%EF%BC%89%20%E4%B8%AD%E5%B1%B1%E5%8D%80%20%E8%87%BA%E5%8C%97%E5%B8%82 | J3: https://www.google.com/maps?q=25.069100,121.532300 | K3: P0｜核心
A4: 13 | B4: 臺北市 | C4: 中山區 | D4: 大佳河濱公園 | E4: 25.0727 | F4: 121.535 | G4: C｜Google Maps 需人工選定主地標 | H4: 線性／跨區場域代表點 | I4: https://www.google.com/maps/search/?api=1&query=%E5%A4%A7%E4%BD%B3%E6%B2%B3%E6%BF%B1%E5%85%AC%E5%9C%92%20%E4%B8%AD%E5%B1%B1%E5%8D%80%20%E8%87%BA%E5%8C%97%E5%B8%82 | J4: https://www.google.com/maps?q=25.072700,121.535000 | K4: P0｜核心
A5: 14 | B5: 臺北市 | C5: 中山區 | D5: 美堤河濱公園 | E5: 25.0784 | F5: 121.5555 | G5: C｜Google Maps 需人工選定主地標 | H5: 線性／跨區場域代表點 | I5: https://www.google.com/maps/search/?api=1&query=%E7%BE%8E%E5%A0%A4%E6%B2%B3%E6%BF%B1%E5%85%AC%E5%9C%92%20%E4%B8%AD%E5%B1%B1%E5%8D%80%20%E8%87%BA%E5%8C%97%E5%B8%82 | J5: https://www.google.com/maps?q=25.078400,121.555500 | K5: P1｜擴充
A6: 15 | B6: 臺北市 | C6: 松山區 | D6: 彩虹河濱公園 | E6: 25.0505 | F6: 121.5775 | G6: C｜Google Maps 需人工選定主地標 | H6: 線性／跨區場域代表點 | I6: https://www.google.com/maps/search/?api=1&query=%E5%BD%A9%E8%99%B9%E6%B2%B3%E6%BF%B1%E5%85%AC%E5%9C%92%20%E6%9D%BE%E5%B1%B1%E5%8D%80%20%E8%87%BA%E5%8C%97%E5%B8%82 | J6: https://www.google.com/maps?q=25.050500,121.577500 | K6: P1｜擴充
A7: 16 | B7: 臺北市 | C7: 萬華區 | D7: 華中河濱公園 | E7: 25.0199 | F7: 121.5046 | G7: C｜Google Maps 需人工選定主地標 | H7: 線性／跨區場域代表點 | I7: https://www.google.com/maps/search/?api=1&query=%E8%8F%AF%E4%B8%AD%E6%B2%B3%E6%BF%B1%E5%85%AC%E5%9C%92%20%E8%90%AC%E8%8F%AF%E5%8D%80%20%E8%87%BA%E5%8C%97%E5%B8%82 | J7: https://www.google.com/maps?q=25.019900,121.504600 | K7: P1｜擴充
A8: 17 | B8: 臺北市 | C8: 士林區 | D8: 百齡河濱公園 | E8: 25.0881 | F8: 121.5176 | G8: C｜Google Maps 需人工選定主地標 | H8: 線性／跨區場域代表點 | I8: https://www.google.com/maps/search/?api=1&query=%E7%99%BE%E9%BD%A1%E6%B2%B3%E6%BF%B1%E5%85%AC%E5%9C%92%20%E5%A3%AB%E6%9E%97%E5%8D%80%20%E8%87%BA%E5%8C%97%E5%B8%82 | J8: https://www.google.com/maps?q=25.088100,121.517600 | K8: P1｜擴充
A9: 18 | B9: 臺北市 | C9: 北投區 | D9: 關渡自然公園 | E9: 25.1199 | F9: 121.4697 | G9: B｜Google Maps 名稱搜尋待核對 | H9: 景區／公共園區 POI | I9: https://www.google.com/maps/search/?api=1&query=%E9%97%9C%E6%B8%A1%E8%87%AA%E7%84%B6%E5%85%AC%E5%9C%92%20%E5%8C%97%E6%8A%95%E5%8D%80%20%E8%87%BA%E5%8C%97%E5%B8%82 | J9: https://www.google.com/maps?q=25.119900,121.469700 | K9: P1｜擴充
A10: 22 | B10: 新北市 | C10: 中和區 | D10: 八二三紀念公園（四號公園） | E10: 25.0016 | F10: 121.5144 | G10: C｜Google Maps 需人工選定主地標 | H10: 複合／多園區地標 | I10: https://www.google.com/maps/search/?api=1&query=%E5%85%AB%E4%BA%8C%E4%B8%89%E7%B4%80%E5%BF%B5%E5%85%AC%E5%9C%92%EF%BC%88%E5%9B%9B%E8%99%9F%E5%85%AC%E5%9C%92%EF%BC%89%20%E4%B8%AD%E5%92%8C%E5%8D%80%20%E6%96%B0%E5%8C%97%E5%B8%82 | J10: https://www.google.com/maps?q=25.001600,121.514400 | K10: P0｜核心
A11: 23 | B11: 新北市 | C11: 板橋區 | D11: 新板萬坪都會公園 | E11: 25.0126 | F11: 121.4628 | G11: B｜Google Maps 名稱搜尋待核對 | H11: 單一公園 POI | I11: https://www.google.com/maps/search/?api=1&query=%E6%96%B0%E6%9D%BF%E8%90%AC%E5%9D%AA%E9%83%BD%E6%9C%83%E5%85%AC%E5%9C%92%20%E6%9D%BF%E6%A9%8B%E5%8D%80%20%E6%96%B0%E5%8C%97%E5%B8%82 | J11: https://www.google.com/maps?q=25.012600,121.462800 | K11: P0｜核心
A12: 24 | B12: 新北市 | C12: 板橋區 | D12: 板橋435藝文特區戶外園區 | E12: 25.0238 | F12: 121.4515 | G12: B｜Google Maps 名稱搜尋待核對 | H12: 景區／公共園區 POI | I12: https://www.google.com/maps/search/?api=1&query=%E6%9D%BF%E6%A9%8B435%E8%97%9D%E6%96%87%E7%89%B9%E5%8D%80%E6%88%B6%E5%A4%96%E5%9C%92%E5%8D%80%20%E6%9D%BF%E6%A9%8B%E5%8D%80%20%E6%96%B0%E5%8C%97%E5%B8%82 | J12: https://www.google.com/maps?q=25.023800,121.451500 | K12: P1｜擴充
A13: 25 | B13: 新北市 | C13: 永和區 | D13: 仁愛公園 | E13: 25.0096 | F13: 121.509 | G13: B｜Google Maps 名稱搜尋待核對 | H13: 單一公園 POI | I13: https://www.google.com/maps/search/?api=1&query=%E4%BB%81%E6%84%9B%E5%85%AC%E5%9C%92%20%E6%B0%B8%E5%92%8C%E5%8D%80%20%E6%96%B0%E5%8C%97%E5%B8%82 | J13: https://www.google.com/maps?q=25.009600,121.509000 | K13: P1｜擴充
A14: 29 | B14: 新北市 | C14: 永和區 | D14: 綠寶石河濱公園 | E14: 25.0115 | F14: 121.5116 | G14: C｜Google Maps 需人工選定主地標 | H14: 線性／跨區場域代表點 | I14: https://www.google.com/maps/search/?api=1&query=%E7%B6%A0%E5%AF%B6%E7%9F%B3%E6%B2%B3%E6%BF%B1%E5%85%AC%E5%9C%92%20%E6%B0%B8%E5%92%8C%E5%8D%80%20%E6%96%B0%E5%8C%97%E5%B8%82 | J14: https://www.google.com/maps?q=25.011500,121.511600 | K14: P1｜擴充
... A186: 231 | B186: 連江縣 | C186: 南竿鄉 | D186: 馬祖民俗文物館園區 | E186: 26.1569 | F186: 119.9515 | G186: C｜Google Maps 優先複核 | H186: 景區／公共園區 POI | I186: https://www.google.com/maps/search/?api=1&query=%E9%A6%AC%E7%A5%96%E6%B0%91%E4%BF%97%E6%96%87%E7%89%A9%E9%A4%A8%E5%9C%92%E5%8D%80%20%E5%8D%97%E7%AB%BF%E9%84%89%20%E9%80%A3%E6%B1%9F%E7%B8%A3 | J186: https://www.google.com/maps?q=26.156900,119.951500 | K186: P1｜擴充

Sheet 新增六章節總表
A1: DOR｜城市探索 六大散步章節母清單｜150處｜Google Maps座標基準｜2026-07-13
A2: 地點ID | B2: 縣市 | C2: 行政區 | D2: 類型 | E2: 地點名稱 | F2: 打卡點定位 | G2: 緯度（WGS84） | H2: 經度（WGS84） | I2: 星等 | J2: 星等顯示 | K2: 熱門理由 | L2: 建議任務 | M2: 開放性備註 | N2: GPS半徑建議m | O2: 座標可信度 | P2: 座標設定說明 | Q2: 資料來源類型 | R2: 資料來源URL | S2: 整理日期 | T2: 主類別 | U2: 章節 | V2: 散步適合度 | W2: 建議時間 | X2: 建議距離km | Y2: 任務節點建議 | Z2: DOR收錄優先級 | AA2: Google Maps地標搜尋 | AB2: Google Maps座標檢視 | AC2: 座標場域類型 | AD2: 去重備註 | AE2: 與既有公園資料關係
A3: DOR-TPE-HIS-001 | B3: 臺北市 | C3: 大同區 | D3: 老街／歷史街區 | E3: 迪化街－年貨大街 | F3: Google Maps 街區主地標／主要入口代表點 | G3: 25.055104 | H3: 121.51003 | I3: 5 | J3: ★★★★★ | K3: 迪化街－年貨大街具街屋、巷弄、廟宇與地方生活集中，適合用步行解鎖城鎮記憶。 | L3: 迪化街－年貨大街散步任務｜完成街區主街、支巷與代表地標三段探索，拍攝一處建築細節並完成終點打卡。記錄一個只有步行時才會注意到的細節。 | M3: 公共街區為主；請注意車流、居民生活、商家營業時間及活動管制。 | N3: 200 | O3: B｜Google 場域代表點 | P3: 採觀光署景點資料之 Google 場域代表座標；歷史街區不應直接等同唯一 GPS 任務圓心，需再選定起點、途中節點與終點。 | Q3: 交通部觀光署觀光資訊資料庫（座標地圖以 Google 為主） | R3: https://data.gov.tw/dataset/7777 | S3: 2026-07-13 | T3: 城市散步 | U3: 01｜老街與歷史街區 | V3: 高 | W3: 40–60 分鐘 | X3: 1.8 | Y3: 街區入口或牌樓／主要街屋與支巷／歷史地標或終點廣場 | Z3: P0｜核心 | AA3: https://www.google.com/maps/search/?api=1&query=%E8%BF%AA%E5%8C%96%E8%A1%97%EF%BC%8D%E5%B9%B4%E8%B2%A8%E5%A4%A7%E8%A1%97%20%E5%A4%A7%E5%90%8C%E5%8D%80%20%E8%87%BA%E5%8C%97%E5%B8%82 | AB3: https://www.google.com/maps?q=25.055104,121.510030 | AC3: 街區／聚落代表點 | AD3: 新增六章節資料；正式合併 DOR 主表前，請以名稱、行政區及 300 公尺內座標進行去重。 | AE3: 否｜建議新增場域
A4: DOR-TPE-HIS-002 | B4: 臺北市 | C4: 萬華區 | D4: 老街／歷史街區 | E4: 剝皮寮老街 | F4: Google Maps 街區主地標／主要入口代表點 | G4: 25.036838 | H4: 121.50216 | I4: 5 | J4: ★★★★★ | K4: 剝皮寮老街具街屋、巷弄、廟宇與地方生活集中，適合用步行解鎖城鎮記憶。 | L4: 剝皮寮老街散步任務｜完成街區主街、支巷與代表地標三段探索，拍攝一處建築細節並完成終點打卡。以起點、途中與終點三張照片完成探索紀錄。 | M4: 公共街區為主；請注意車流、居民生活、商家營業時間及活動管制。 | N4: 200 | O4: B｜Google 場域代表點 | P4: 採觀光署景點資料之 Google 場域代表座標；歷史街區不應直接等同唯一 GPS 任務圓心，需再選定起點、途中節點與終點。 | Q4: 交通部觀光署觀光資訊資料庫（座標地圖以 Google 為主） | R4: https://data.gov.tw/dataset/7777 | S4: 2026-07-13 | T4: 城市散步 | U4: 01｜老街與歷史街區 | V4: 高 | W4: 40–60 分鐘 | X4: 1.8 | Y4: 街區入口或牌樓／主要街屋與支巷／歷史地標或終點廣場 | Z4: P0｜核心 | AA4: https://www.google.com/maps/search/?api=1&query=%E5%89%9D%E7%9A%AE%E5%AF%AE%E8%80%81%E8%A1%97%20%E8%90%AC%E8%8F%AF%E5%8D%80%20%E8%87%BA%E5%8C%97%E5%B8%82 | AB4: https://www.google.com/maps?q=25.036838,121.502160 | AC4: 街區／聚落代表點 | AD4: 新增六章節資料；正式合併 DOR 主表前，請以名稱、行政區及 300 公尺內座標進行去重。 | AE4: 否｜建議新增場域
A5: DOR-NTP-HIS-001 | B5: 新北市 | C5: 瑞芳區 | D5: 老街／歷史街區 | E5: 九份 | F5: Google Maps 街區主地標／主要入口代表點 | G5: 25.109819 | H5: 121.84341 | I5: 5 | J5: ★★★★★ | K5: 九份具街屋、巷弄、廟宇與地方生活集中，適合用步行解鎖城鎮記憶。 | L5: 九份散步任務｜完成街區主街、支巷與代表地標三段探索，拍攝一處建築細節並完成終點打卡。在終點回答一題與場域故事有關的問題。 | M5: 公共街區為主；請注意車流、居民生活、商家營業時間及活動管制。 | N5: 200 | O5: B｜Google 場域代表點 | P5: 採觀光署景點資料之 Google 場域代表座標；歷史街區不應直接等同唯一 GPS 任務圓心，需再選定起點、途中節點與終點。 | Q5: 交通部觀光署觀光資訊資料庫（座標地圖以 Google 為主） | R5: https://data.gov.tw/dataset/7777 | S5: 2026-07-13 | T5: 城市散步 | U5: 01｜老街與歷史街區 | V5: 高 | W5: 40–60 分鐘 | X5: 1.8 | Y5: 街區入口或牌樓／主要街屋與支巷／歷史地標或終點廣場 | Z5: P0｜核心 | AA5: https://www.google.com/maps/search/?api=1&query=%E4%B9%9D%E4%BB%BD%20%E7%91%9E%E8%8A%B3%E5%8D%80%20%E6%96%B0%E5%8C%97%E5%B8%82 | AB5: https://www.google.com/maps?q=25.109819,121.843410 | AC5: 街區／聚落代表點 | AD5: 新增六章節資料；正式合併 DOR 主表前，請以名稱、行政區及 300 公尺內座標進行去重。 | AE5: 否｜建議新增場域
A6: DOR-NTP-HIS-002 | B6: 新北市 | C6: 淡水區 | D6: 老街／歷史街區 | E6: 淡水老街 | F6: Google Maps 街區主地標／主要入口代表點 | G6: 25.171038 | H6: 121.43895 | I6: 5 | J6: ★★★★★ | K6: 淡水老街具街屋、巷弄、廟宇與地方生活集中，適合用步行解鎖城鎮記憶。 | L6: 淡水老街散步任務｜完成街區主街、支巷與代表地標三段探索，拍攝一處建築細節並完成終點打卡。沿途至少完成三個檢查點。 | M6: 公共街區為主；請注意車流、居民生活、商家營業時間及活動管制。 | N6: 200 | O6: B｜Google 場域代表點 | P6: 採觀光署景點資料之 Google 場域代表座標；歷史街區不應直接等同唯一 GPS 任務圓心，需再選定起點、途中節點與終點。 | Q6: 交通部觀光署觀光資訊資料庫（座標地圖以 Google 為主） | R6: https://data.gov.tw/dataset/7777 | S6: 2026-07-13 | T6: 城市散步 | U6: 01｜老街與歷史街區 | V6: 高 | W6: 40–60 分鐘 | X6: 1.8 | Y6: 街區入口或牌樓／主要街屋與支巷／歷史地標或終點廣場 | Z6: P0｜核心 | AA6: https://www.google.com/maps/search/?api=1&query=%E6%B7%A1%E6%B0%B4%E8%80%81%E8%A1%97%20%E6%B7%A1%E6%B0%B4%E5%8D%80%20%E6%96%B0%E5%8C%97%E5%B8%82 | AB6: https://www.google.com/maps?q=25.171038,121.438950 | AC6: 街區／聚落代表點 | AD6: 新增六章節資料；正式合併 DOR 主表前，請以名稱、行政區及 300 公尺內座標進行去重。 | AE6: 否｜建議新增場域
A7: DOR-NTP-HIS-003 | B7: 新北市 | C7: 三峽區 | D7: 老街／歷史街區 | E7: 三峽老街 | F7: Google Maps 街區主地標／主要入口代表點 | G7: 24.934516 | H7: 121.37029 | I7: 5 | J7: ★★★★★ | K7: 三峽老街具街屋、巷弄、廟宇與地方生活集中，適合用步行解鎖城鎮記憶。 | L7: 三峽老街散步任務｜完成街區主街、支巷與代表地標三段探索，拍攝一處建築細節並完成終點打卡。記錄一個只有步行時才會注意到的細節。 | M7: 公共街區為主；請注意車流、居民生活、商家營業時間及活動管制。 | N7: 200 | O7: B｜Google 場域代表點 | P7: 採觀光署景點資料之 Google 場域代表座標；歷史街區不應直接等同唯一 GPS 任務圓心，需再選定起點、途中節點與終點。 | Q7: 交通部觀光署觀光資訊資料庫（座標地圖以 Google 為主） | R7: https://data.gov.tw/dataset/7777 | S7: 2026-07-13 | T7: 城市散步 | U7: 01｜老街與歷史街區 | V7: 高 | W7: 40–60 分鐘 | X7: 1.8 | Y7: 街區入口或牌樓／主要街屋與支巷／歷史地標或終點廣場 | Z7: P0｜核心 | AA7: https://www.google.com/maps/search/?api=1&query=%E4%B8%89%E5%B3%BD%E8%80%81%E8%A1%97%20%E4%B8%89%E5%B3%BD%E5%8D%80%20%E6%96%B0%E5%8C%97%E5%B8%82 | AB7: https://www.google.com/maps?q=24.934516,121.370290 | AC7: 街區／聚落代表點 | AD7: 新增六章節資料；正式合併 DOR 主表前，請以名稱、行政區及 300 公尺內座標進行去重。 | AE7: 否｜建議新增場域
A8: DOR-NTP-HIS-004 | B8: 新北市 | C8: 金山區 | D8: 老街／歷史街區 | E8: 金山老街（金包里老街） | F8: Google Maps 街區主地標／主要入口代表點 | G8: 25.221824 | H8: 121.63826 | I8: 4 | J8: ★★★★☆ | K8: 金山老街（金包里老街）具街屋、巷弄、廟宇與地方生活集中，適合用步行解鎖城鎮記憶。 | L8: 金山老街（金包里老街）散步任務｜完成街區主街、支巷與代表地標三段探索，拍攝一處建築細節並完成終點打卡。以起點、途中與終點三張照片完成探索紀錄。 | M8: 公共街區為主；請注意車流、居民生活、商家營業時間及活動管制。 | N8: 200 | O8: B｜Google 場域代表點 | P8: 採觀光署景點資料之 Google 場域代表座標；歷史街區不應直接等同唯一 GPS 任務圓心，需再選定起點、途中節點與終點。 | Q8: 交通部觀光署觀光資訊資料庫（座標地圖以 Google 為主） | R8: https://data.gov.tw/dataset/7777 | S8: 2026-07-13 | T8: 城市散步 | U8: 01｜老街與歷史街區 | V8: 高 | W8: 40–60 分鐘 | X8: 1.8 | Y8: 街區入口或牌樓／主要街屋與支巷／歷史地標或終點廣場 | Z8: P1｜擴充 | AA8: https://www.google.com/maps/search/?api=1&query=%E9%87%91%E5%B1%B1%E8%80%81%E8%A1%97%EF%BC%88%E9%87%91%E5%8C%85%E9%87%8C%E8%80%81%E8%A1%97%EF%BC%89%20%E9%87%91%E5%B1%B1%E5%8D%80%20%E6%96%B0%E5%8C%97%E5%B8%82 | AB8: https://www.google.com/maps?q=25.221824,121.638260 | AC8: 街區／聚落代表點 | AD8: 新增六章節資料；正式合併 DOR 主表前，請以名稱、行政區及 300 公尺內座標進行去重。 | AE8: 否｜建議新增場域
A9: DOR-NTP-HIS-005 | B9: 新北市 | C9: 深坑區 | D9: 老街／歷史街區 | E9: 深坑老街 | F9: Google Maps 街區主地標／主要入口代表點 | G9: 25.001691 | H9: 121.61473 | I9: 4 | J9: ★★★★☆ | K9: 深坑老街具街屋、巷弄、廟宇與地方生活集中，適合用步行解鎖城鎮記憶。 | L9: 深坑老街散步任務｜完成街區主街、支巷與代表地標三段探索，拍攝一處建築細節並完成終點打卡。在終點回答一題與場域故事有關的問題。 | M9: 公共街區為主；請注意車流、居民生活、商家營業時間及活動管制。 | N9: 200 | O9: B｜Google 場域代表點 | P9: 採觀光署景點資料之 Google 場域代表座標；歷史街區不應直接等同唯一 GPS 任務圓心，需再選定起點、途中節點與終點。 | Q9: 交通部觀光署觀光資訊資料庫（座標地圖以 Google 為主） | R9: https://data.gov.tw/dataset/7777 | S9: 2026-07-13 | T9: 城市散步 | U9: 01｜老街與歷史街區 | V9: 高 | W9: 40–60 分鐘 | X9: 1.8 | Y9: 街區入口或牌樓／主要街屋與支巷／歷史地標或終點廣場 | Z9: P1｜擴充 | AA9: https://www.google.com/maps/search/?api=1&query=%E6%B7%B1%E5%9D%91%E8%80%81%E8%A1%97%20%E6%B7%B1%E5%9D%91%E5%8D%80%20%E6%96%B0%E5%8C%97%E5%B8%82 | AB9: https://www.google.com/maps?q=25.001691,121.614730 | AC9: 街區／聚落代表點 | AD9: 新增六章節資料；正式合併 DOR 主表前，請以名稱、行政區及 300 公尺內座標進行去重。 | AE9: 否｜建議新增場域
A10: DOR-TAO-HIS-001 | B10: 桃園市 | C10: 大溪區 | D10: 老街／歷史街區 | E10: 大溪老街 | F10: Google Maps 街區主地標／主要入口代表點 | G10: 24.885186 | H10: 121.28747 | I10: 5 | J10: ★★★★★ | K10: 大溪老街具街屋、巷弄、廟宇與地方生活集中，適合用步行解鎖城鎮記憶。 | L10: 大溪老街散步任務｜完成街區主街、支巷與代表地標三段探索，拍攝一處建築細節並完成終點打卡。沿途至少完成三個檢查點。 | M10: 公共街區為主；請注意車流、居民生活、商家營業時間及活動管制。 | N10: 200 | O10: B｜Google 場域代表點 | P10: 採觀光署景點資料之 Google 場域代表座標；歷史街區不應直接等同唯一 GPS 任務圓心，需再選定起點、途中節點與終點。 | Q10: 交通部觀光署觀光資訊資料庫（座標地圖以 Google 為主） | R10: https://data.gov.tw/dataset/7777 | S10: 2026-07-13 | T10: 城市散步 | U10: 01｜老街與歷史街區 | V10: 高 | W10: 40–60 分鐘 | X10: 1.8 | Y10: 街區入口或牌樓／主要街屋與支巷／歷史地標或終點廣場 | Z10: P0｜核心 | AA10: https://www.google.com/maps/search/?api=1&query=%E5%A4%A7%E6%BA%AA%E8%80%81%E8%A1%97%20%E5%A4%A7%E6%BA%AA%E5%8D%80%20%E6%A1%83%E5%9C%92%E5%B8%82 | AB10: https://www.google.com/maps?q=24.885186,121.287470 | AC10: 街區／聚落代表點 | AD10: 新增六章節資料；正式合併 DOR 主表前，請以名稱、行政區及 300 公尺內座標進行去重。 | AE10: 否｜建議新增場域
A11: DOR-TAO-HIS-002 | B11: 桃園市 | C11: 龍潭區 | D11: 老街／歷史街區 | E11: 三坑老街 | F11: Google Maps 街區主地標／主要入口代表點 | G11: 24.843865 | H11: 121.24799 | I11: 4 | J11: ★★★★☆ | K11: 三坑老街具街屋、巷弄、廟宇與地方生活集中，適合用步行解鎖城鎮記憶。 | L11: 三坑老街散步任務｜完成街區主街、支巷與代表地標三段探索，拍攝一處建築細節並完成終點打卡。記錄一個只有步行時才會注意到的細節。 | M11: 公共街區為主；請注意車流、居民生活、商家營業時間及活動管制。 | N11: 200 | O11: B｜Google 場域代表點 | P11: 採觀光署景點資料之 Google 場域代表座標；歷史街區不應直接等同唯一 GPS 任務圓心，需再選定起點、途中節點與終點。 | Q11: 交通部觀光署觀光資訊資料庫（座標地圖以 Google 為主） | R11: https://data.gov.tw/dataset/7777 | S11: 2026-07-13 | T11: 城市散步 | U11: 01｜老街與歷史街區 | V11: 高 | W11: 40–60 分鐘 | X11: 1.8 | Y11: 街區入口或牌樓／主要街屋與支巷／歷史地標或終點廣場 | Z11: P1｜擴充 | AA11: https://www.google.com/maps/search/?api=1&query=%E4%B8%89%E5%9D%91%E8%80%81%E8%A1%97%20%E9%BE%8D%E6%BD%AD%E5%8D%80%20%E6%A1%83%E5%9C%92%E5%B8%82 | AB11: https://www.google.com/maps?q=24.843865,121.247990 | AC11: 街區／聚落代表點 | AD11: 新增六章節資料；正式合併 DOR 主表前，請以名稱、行政區及 300 公尺內座標進行去重。 | AE11: 否｜建議新增場域
A12: DOR-TAO-HIS-003 | B12: 桃園市 | C12: 楊梅區 | D12: 老街／歷史街區 | E12: 富岡老街 | F12: Google Maps 街區主地標／主要入口代表點 | G12: 24.936328 | H12: 121.08243 | I12: 4 | J12: ★★★★☆ | K12: 富岡老街具街屋、巷弄、廟宇與地方生活集中，適合用步行解鎖城鎮記憶。 | L12: 富岡老街散步任務｜完成街區主街、支巷與代表地標三段探索，拍攝一處建築細節並完成終點打卡。以起點、途中與終點三張照片完成探索紀錄。 | M12: 公共街區為主；請注意車流、居民生活、商家營業時間及活動管制。 | N12: 200 | O12: B｜Google 場域代表點 | P12: 採觀光署景點資料之 Google 場域代表座標；歷史街區不應直接等同唯一 GPS 任務圓心，需再選定起點、途中節點與終點。 | Q12: 交通部觀光署觀光資訊資料庫（座標地圖以 Google 為主） | R12: https://data.gov.tw/dataset/7777 | S12: 2026-07-13 | T12: 城市散步 | U12: 01｜老街與歷史街區 | V12: 高 | W12: 40–60 分鐘 | X12: 1.8 | Y12: 街區入口或牌樓／主要街屋與支巷／歷史地標或終點廣場 | Z12: P1｜擴充 | AA12: https://www.google.com/maps/search/?api=1&query=%E5%AF%8C%E5%B2%A1%E8%80%81%E8%A1%97%20%E6%A5%8A%E6%A2%85%E5%8D%80%20%E6%A1%83%E5%9C%92%E5%B8%82 | AB12: https://www.google.com/maps?q=24.936328,121.082430 | AC12: 街區／聚落代表點 | AD12: 新增六章節資料；正式合併 DOR 主表前，請以名稱、行政區及 300 公尺內座標進行去重。 | AE12: 否｜建議新增場域
A13: DOR-HSQ-HIS-001 | B13: 新竹縣 | C13: 北埔鄉 | D13: 老街／歷史街區 | E13: 北埔老街 | F13: Google Maps 街區主地標／主要入口代表點 | G13: 24.699816 | H13: 121.05722 | I13: 5 | J13: ★★★★★ | K13: 北埔老街具街屋、巷弄、廟宇與地方生活集中，適合用步行解鎖城鎮記憶。 | L13: 北埔老街散步任務｜完成街區主街、支巷與代表地標三段探索，拍攝一處建築細節並完成終點打卡。在終點回答一題與場域故事有關的問題。 | M13: 公共街區為主；請注意車流、居民生活、商家營業時間及活動管制。 | N13: 200 | O13: B｜Google 場域代表點 | P13: 採觀光署景點資料之 Google 場域代表座標；歷史街區不應直接等同唯一 GPS 任務圓心，需再選定起點、途中節點與終點。 | Q13: 交通部觀光署觀光資訊資料庫（座標地圖以 Google 為主） | R13: https://data.gov.tw/dataset/7777 | S13: 2026-07-13 | T13: 城市散步 | U13: 01｜老街與歷史街區 | V13: 高 | W13: 40–60 分鐘 | X13: 1.8 | Y13: 街區入口或牌樓／主要街屋與支巷／歷史地標或終點廣場 | Z13: P0｜核心 | AA13: https://www.google.com/maps/search/?api=1&query=%E5%8C%97%E5%9F%94%E8%80%81%E8%A1%97%20%E5%8C%97%E5%9F%94%E9%84%89%20%E6%96%B0%E7%AB%B9%E7%B8%A3 | AB13: https://www.google.com/maps?q=24.699816,121.057220 | AC13: 街區／聚落代表點 | AD13: 新增六章節資料；正式合併 DOR 主表前，請以名稱、行政區及 300 公尺內座標進行去重。 | AE13: 否｜建議新增場域
A14: DOR-HSQ-HIS-002 | B14: 新竹縣 | C14: 湖口鄉 | D14: 老街／歷史街區 | E14: 湖口老街 | F14: Google Maps 街區主地標／主要入口代表點 | G14: 24.876872 | H14: 121.05514 | I14: 4 | J14: ★★★★☆ | K14: 湖口老街具街屋、巷弄、廟宇與地方生活集中，適合用步行解鎖城鎮記憶。 | L14: 湖口老街散步任務｜完成街區主街、支巷與代表地標三段探索，拍攝一處建築細節並完成終點打卡。沿途至少完成三個檢查點。 | M14: 公共街區為主；請注意車流、居民生活、商家營業時間及活動管制。 | N14: 200 | O14: B｜Google 場域代表點 | P14: 採觀光署景點資料之 Google 場域代表座標；歷史街區不應直接等同唯一 GPS 任務圓心，需再選定起點、途中節點與終點。 | Q14: 交通部觀光署觀光資訊資料庫（座標地圖以 Google 為主） | R14: https://data.gov.tw/dataset/7777 | S14: 2026-07-13 | T14: 城市散步 | U14: 01｜老街與歷史街區 | V14: 高 | W14: 40–60 分鐘 | X14: 1.8 | Y14: 街區入口或牌樓／主要街屋與支巷／歷史地標或終點廣場 | Z14: P1｜擴充 | AA14: https://www.google.com/maps/search/?api=1&query=%E6%B9%96%E5%8F%A3%E8%80%81%E8%A1%97%20%E6%B9%96%E5%8F%A3%E9%84%89%20%E6%96%B0%E7%AB%B9%E7%B8%A3 | AB14: https://www.google.com/maps?q=24.876872,121.055140 | AC14: 街區／聚落代表點 | AD14: 新增六章節資料；正式合併 DOR 主表前，請以名稱、行政區及 300 公尺內座標進行去重。 | AE14: 否｜建議新增場域
... A152: DOR-TTT-ART-001 | B152: 臺東縣 | C152: 臺東市 | D152: 公共藝術／特色建築 | E152: 卑南遺址公園 | F152: 建築主入口／公共藝術核心地標 | G152: 22.792165 | H152: 121.11593 | I152: 5 | J152: ★★★★★ | K152: 卑南遺址公園具建築輪廓、公共藝術與觀看角度具高度分享性，適合觀察與拍照型探索。 | L152: 卑南遺址公園散步任務｜完成建築外觀巡遊，尋找一件公共藝術或特色細節，從指定角度拍照後終點打卡。記錄一個只有步行時才會注意到的細節。 | M152: 戶外空間優先；室內展館需確認開放時間、門票、拍攝與活動管制。 | N152: 120 | O152: A｜觀光署 Google 基準 POI | P152: 採觀光署景點資料之 Google 基準 POI 座標；正式上線前仍應確認圖釘名稱、入口與實際步行動線。 | Q152: 交通部觀光署觀光資訊資料庫（座標地圖以 Google 為主） | R152: https://data.gov.tw/dataset/7777 | S152: 2026-07-13 | T152: 城市散步 | U152: 06｜公共藝術與特色建築 | V152: 高 | W152: 35–60 分鐘 | X152: 1.5 | Y152: 主入口或建築正面／公共藝術或立面細節／最佳觀看角度或廣場終點 | Z152: P0｜核心 | AA152: https://www.google.com/maps/search/?api=1&query=%E5%8D%91%E5%8D%97%E9%81%BA%E5%9D%80%E5%85%AC%E5%9C%92%20%E8%87%BA%E6%9D%B1%E5%B8%82%20%E8%87%BA%E6%9D%B1%E7%B8%A3 | AB152: https://www.google.com/maps?q=22.792165,121.115930 | AC152: 建築／公共藝術 POI | AD152: 新增六章節資料；正式合併 DOR 主表前，請以名稱、行政區及 300 公尺內座標進行去重。 | AE152: 否｜建議新增場域

Sheet 01老街歷史街區
A1: DOR｜城市探索 01｜老街與歷史街區｜共 25 處
A2: 地點ID | B2: 縣市 | C2: 行政區 | D2: 類型 | E2: 地點名稱 | F2: 打卡點定位 | G2: 緯度（WGS84） | H2: 經度（WGS84） | I2: 星等 | J2: 星等顯示 | K2: 熱門理由 | L2: 建議任務 | M2: 開放性備註 | N2: GPS半徑建議m | O2: 座標可信度 | P2: 座標設定說明 | Q2: 資料來源類型 | R2: 資料來源URL | S2: 整理日期 | T2: 主類別 | U2: 章節 | V2: 散步適合度 | W2: 建議時間 | X2: 建議距離km | Y2: 任務節點建議 | Z2: DOR收錄優先級 | AA2: Google Maps地標搜尋 | AB2: Google Maps座標檢視 | AC2: 座標場域類型 | AD2: 去重備註 | AE2: 與既有公園資料關係
A3: DOR-TPE-HIS-001 | B3: 臺北市 | C3: 大同區 | D3: 老街／歷史街區 | E3: 迪化街－年貨大街 | F3: Google Maps 街區主地標／主要入口代表點 | G3: 25.055104 | H3: 121.51003 | I3: 5 | J3: ★★★★★ | K3: 迪化街－年貨大街具街屋、巷弄、廟宇與地方生活集中，適合用步行解鎖城鎮記憶。 | L3: 迪化街－年貨大街散步任務｜完成街區主街、支巷與代表地標三段探索，拍攝一處建築細節並完成終點打卡。記錄一個只有步行時才會注意到的細節。 | M3: 公共街區為主；請注意車流、居民生活、商家營業時間及活動管制。 | N3: 200 | O3: B｜Google 場域代表點 | P3: 採觀光署景點資料之 Google 場域代表座標；歷史街區不應直接等同唯一 GPS 任務圓心，需再選定起點、途中節點與終點。 | Q3: 交通部觀光署觀光資訊資料庫（座標地圖以 Google 為主） | R3: https://data.gov.tw/dataset/7777 | S3: 2026-07-13 | T3: 城市散步 | U3: 01｜老街與歷史街區 | V3: 高 | W3: 40–60 分鐘 | X3: 1.8 | Y3: 街區入口或牌樓／主要街屋與支巷／歷史地標或終點廣場 | Z3: P0｜核心 | AA3: https://www.google.com/maps/search/?api=1&query=%E8%BF%AA%E5%8C%96%E8%A1%97%EF%BC%8D%E5%B9%B4%E8%B2%A8%E5%A4%A7%E8%A1%97%20%E5%A4%A7%E5%90%8C%E5%8D%80%20%E8%87%BA%E5%8C%97%E5%B8%82 | AB3: https://www.google.com/maps?q=25.055104,121.510030 | AC3: 街區／聚落代表點 | AD3: 新增六章節資料；正式合併 DOR 主表前，請以名稱、行政區及 300 公尺內座標進行去重。 | AE3: 否｜建議新增場域
A4: DOR-TPE-HIS-002 | B4: 臺北市 | C4: 萬華區 | D4: 老街／歷史街區 | E4: 剝皮寮老街 | F4: Google Maps 街區主地標／主要入口代表點 | G4: 25.036838 | H4: 121.50216 | I4: 5 | J4: ★★★★★ | K4: 剝皮寮老街具街屋、巷弄、廟宇與地方生活集中，適合用步行解鎖城鎮記憶。 | L4: 剝皮寮老街散步任務｜完成街區主街、支巷與代表地標三段探索，拍攝一處建築細節並完成終點打卡。以起點、途中與終點三張照片完成探索紀錄。 | M4: 公共街區為主；請注意車流、居民生活、商家營業時間及活動管制。 | N4: 200 | O4: B｜Google 場域代表點 | P4: 採觀光署景點資料之 Google 場域代表座標；歷史街區不應直接等同唯一 GPS 任務圓心，需再選定起點、途中節點與終點。 | Q4: 交通部觀光署觀光資訊資料庫（座標地圖以 Google 為主） | R4: https://data.gov.tw/dataset/7777 | S4: 2026-07-13 | T4: 城市散步 | U4: 01｜老街與歷史街區 | V4: 高 | W4: 40–60 分鐘 | X4: 1.8 | Y4: 街區入口或牌樓／主要街屋與支巷／歷史地標或終點廣場 | Z4: P0｜核心 | AA4: https://www.google.com/maps/search/?api=1&query=%E5%89%9D%E7%9A%AE%E5%AF%AE%E8%80%81%E8%A1%97%20%E8%90%AC%E8%8F%AF%E5%8D%80%20%E8%87%BA%E5%8C%97%E5%B8%82 | AB4: https://www.google.com/maps?q=25.036838,121.502160 | AC4: 街區／聚落代表點 | AD4: 新增六章節資料；正式合併 DOR 主表前，請以名稱、行政區及 300 公尺內座標進行去重。 | AE4: 否｜建議新增場域
A5: DOR-NTP-HIS-001 | B5: 新北市 | C5: 瑞芳區 | D5: 老街／歷史街區 | E5: 九份 | F5: Google Maps 街區主地標／主要入口代表點 | G5: 25.109819 | H5: 121.84341 | I5: 5 | J5: ★★★★★ | K5: 九份具街屋、巷弄、廟宇與地方生活集中，適合用步行解鎖城鎮記憶。 | L5: 九份散步任務｜完成街區主街、支巷與代表地標三段探索，拍攝一處建築細節並完成終點打卡。在終點回答一題與場域故事有關的問題。 | M5: 公共街區為主；請注意車流、居民生活、商家營業時間及活動管制。 | N5: 200 | O5: B｜Google 場域代表點 | P5: 採觀光署景點資料之 Google 場域代表座標；歷史街區不應直接等同唯一 GPS 任務圓心，需再選定起點、途中節點與終點。 | Q5: 交通部觀光署觀光資訊資料庫（座標地圖以 Google 為主） | R5: https://data.gov.tw/dataset/7777 | S5: 2026-07-13 | T5: 城市散步 | U5: 01｜老街與歷史街區 | V5: 高 | W5: 40–60 分鐘 | X5: 1.8 | Y5: 街區入口或牌樓／主要街屋與支巷／歷史地標或終點廣場 | Z5: P0｜核心 | AA5: https://www.google.com/maps/search/?api=1&query=%E4%B9%9D%E4%BB%BD%20%E7%91%9E%E8%8A%B3%E5%8D%80%20%E6%96%B0%E5%8C%97%E5%B8%82 | AB5: https://www.google.com/maps?q=25.109819,121.843410 | AC5: 街區／聚落代表點 | AD5: 新增六章節資料；正式合併 DOR 主表前，請以名稱、行政區及 300 公尺內座標進行去重。 | AE5: 否｜建議新增場域
A6: DOR-NTP-HIS-002 | B6: 新北市 | C6: 淡水區 | D6: 老街／歷史街區 | E6: 淡水老街 | F6: Google Maps 街區主地標／主要入口代表點 | G6: 25.171038 | H6: 121.43895 | I6: 5 | J6: ★★★★★ | K6: 淡水老街具街屋、巷弄、廟宇與地方生活集中，適合用步行解鎖城鎮記憶。 | L6: 淡水老街散步任務｜完成街區主街、支巷與代表地標三段探索，拍攝一處建築細節並完成終點打卡。沿途至少完成三個檢查點。 | M6: 公共街區為主；請注意車流、居民生活、商家營業時間及活動管制。 | N6: 200 | O6: B｜Google 場域代表點 | P6: 採觀光署景點資料之 Google 場域代表座標；歷史街區不應直接等同唯一 GPS 任務圓心，需再選定起點、途中節點與終點。 | Q6: 交通部觀光署觀光資訊資料庫（座標地圖以 Google 為主） | R6: https://data.gov.tw/dataset/7777 | S6: 2026-07-13 | T6: 城市散步 | U6: 01｜老街與歷史街區 | V6: 高 | W6: 40–60 分鐘 | X6: 1.8 | Y6: 街區入口或牌樓／主要街屋與支巷／歷史地標或終點廣場 | Z6: P0｜核心 | AA6: https://www.google.com/maps/search/?api=1&query=%E6%B7%A1%E6%B0%B4%E8%80%81%E8%A1%97%20%E6%B7%A1%E6%B0%B4%E5%8D%80%20%E6%96%B0%E5%8C%97%E5%B8%82 | AB6: https://www.google.com/maps?q=25.171038,121.438950 | AC6: 街區／聚落代表點 | AD6: 新增六章節資料；正式合併 DOR 主表前，請以名稱、行政區及 300 公尺內座標進行去重。 | AE6: 否｜建議新增場域
A7: DOR-NTP-HIS-003 | B7: 新北市 | C7: 三峽區 | D7: 老街／歷史街區 | E7: 三峽老街 | F7: Google Maps 街區主地標／主要入口代表點 | G7: 24.934516 | H7: 121.37029 | I7: 5 | J7: ★★★★★ | K7: 三峽老街具街屋、巷弄、廟宇與地方生活集中，適合用步行解鎖城鎮記憶。 | L7: 三峽老街散步任務｜完成街區主街、支巷與代表地標三段探索，拍攝一處建築細節並完成終點打卡。記錄一個只有步行時才會注意到的細節。 | M7: 公共街區為主；請注意車流、居民生活、商家營業時間及活動管制。 | N7: 200 | O7: B｜Google 場域代表點 | P7: 採觀光署景點資料之 Google 場域代表座標；歷史街區不應直接等同唯一 GPS 任務圓心，需再選定起點、途中節點與終點。 | Q7: 交通部觀光署觀光資訊資料庫（座標地圖以 Google 為主） | R7: https://data.gov.tw/dataset/7777 | S7: 2026-07-13 | T7: 城市散步 | U7: 01｜老街與歷史街區 | V7: 高 | W7: 40–60 分鐘 | X7: 1.8 | Y7: 街區入口或牌樓／主要街屋與支巷／歷史地標或終點廣場 | Z7: P0｜核心 | AA7: https://www.google.com/maps/search/?api=1&query=%E4%B8%89%E5%B3%BD%E8%80%81%E8%A1%97%20%E4%B8%89%E5%B3%BD%E5%8D%80%20%E6%96%B0%E5%8C%97%E5%B8%82 | AB7: https://www.google.com/maps?q=24.934516,121.370290 | AC7: 街區／聚落代表點 | AD7: 新增六章節資料；正式合併 DOR 主表前，請以名稱、行政區及 300 公尺內座標進行去重。 | AE7: 否｜建議新增場域
A8: DOR-NTP-HIS-004 | B8: 新北市 | C8: 金山區 | D8: 老街／歷史街區 | E8: 金山老街（金包里老街） | F8: Google Maps 街區主地標／主要入口代表點 | G8: 25.221824 | H8: 121.63826 | I8: 4 | J8: ★★★★☆ | K8: 金山老街（金包里老街）具街屋、巷弄、廟宇與地方生活集中，適合用步行解鎖城鎮記憶。 | L8: 金山老街（金包里老街）散步任務｜完成街區主街、支巷與代表地標三段探索，拍攝一處建築細節並完成終點打卡。以起點、途中與終點三張照片完成探索紀錄。 | M8: 公共街區為主；請注意車流、居民生活、商家營業時間及活動管制。 | N8: 200 | O8: B｜Google 場域代表點 | P8: 採觀光署景點資料之 Google 場域代表座標；歷史街區不應直接等同唯一 GPS 任務圓心，需再選定起點、途中節點與終點。 | Q8: 交通部觀光署觀光資訊資料庫（座標地圖以 Google 為主） | R8: https://data.gov.tw/dataset/7777 | S8: 2026-07-13 | T8: 城市散步 | U8: 01｜老街與歷史街區 | V8: 高 | W8: 40–60 分鐘 | X8: 1.8 | Y8: 街區入口或牌樓／主要街屋與支巷／歷史地標或終點廣場 | Z8: P1｜擴充 | AA8: https://www.google.com/maps/search/?api=1&query=%E9%87%91%E5%B1%B1%E8%80%81%E8%A1%97%EF%BC%88%E9%87%91%E5%8C%85%E9%87%8C%E8%80%81%E8%A1%97%EF%BC%89%20%E9%87%91%E5%B1%B1%E5%8D%80%20%E6%96%B0%E5%8C%97%E5%B8%82 | AB8: https://www.google.com/maps?q=25.221824,121.638260 | AC8: 街區／聚落代表點 | AD8: 新增六章節資料；正式合併 DOR 主表前，請以名稱、行政區及 300 公尺內座標進行去重。 | AE8: 否｜建議新增場域
A9: DOR-NTP-HIS-005 | B9: 新北市 | C9: 深坑區 | D9: 老街／歷史街區 | E9: 深坑老街 | F9: Google Maps 街區主地標／主要入口代表點 | G9: 25.001691 | H9: 121.61473 | I9: 4 | J9: ★★★★☆ | K9: 深坑老街具街屋、巷弄、廟宇與地方生活集中，適合用步行解鎖城鎮記憶。 | L9: 深坑老街散步任務｜完成街區主街、支巷與代表地標三段探索，拍攝一處建築細節並完成終點打卡。在終點回答一題與場域故事有關的問題。 | M9: 公共街區為主；請注意車流、居民生活、商家營業時間及活動管制。 | N9: 200 | O9: B｜Google 場域代表點 | P9: 採觀光署景點資料之 Google 場域代表座標；歷史街區不應直接等同唯一 GPS 任務圓心，需再選定起點、途中節點與終點。 | Q9: 交通部觀光署觀光資訊資料庫（座標地圖以 Google 為主） | R9: https://data.gov.tw/dataset/7777 | S9: 2026-07-13 | T9: 城市散步 | U9: 01｜老街與歷史街區 | V9: 高 | W9: 40–60 分鐘 | X9: 1.8 | Y9: 街區入口或牌樓／主要街屋與支巷／歷史地標或終點廣場 | Z9: P1｜擴充 | AA9: https://www.google.com/maps/search/?api=1&query=%E6%B7%B1%E5%9D%91%E8%80%81%E8%A1%97%20%E6%B7%B1%E5%9D%91%E5%8D%80%20%E6%96%B0%E5%8C%97%E5%B8%82 | AB9: https://www.google.com/maps?q=25.001691,121.614730 | AC9: 街區／聚落代表點 | AD9: 新增六章節資料；正式合併 DOR 主表前，請以名稱、行政區及 300 公尺內座標進行去重。 | AE9: 否｜建議新增場域
A10: DOR-TAO-HIS-001 | B10: 桃園市 | C10: 大溪區 | D10: 老街／歷史街區 | E10: 大溪老街 | F10: Google Maps 街區主地標／主要入口代表點 | G10: 24.885186 | H10: 121.28747 | I10: 5 | J10: ★★★★★ | K10: 大溪老街具街屋、巷弄、廟宇與地方生活集中，適合用步行解鎖城鎮記憶。 | L10: 大溪老街散步任務｜完成街區主街、支巷與代表地標三段探索，拍攝一處建築細節並完成終點打卡。沿途至少完成三個檢查點。 | M10: 公共街區為主；請注意車流、居民生活、商家營業時間及活動管制。 | N10: 200 | O10: B｜Google 場域代表點 | P10: 採觀光署景點資料之 Google 場域代表座標；歷史街區不應直接等同唯一 GPS 任務圓心，需再選定起點、途中節點與終點。 | Q10: 交通部觀光署觀光資訊資料庫（座標地圖以 Google 為主） | R10: https://data.gov.tw/dataset/7777 | S10: 2026-07-13 | T10: 城市散步 | U10: 01｜老街與歷史街區 | V10: 高 | W10: 40–60 分鐘 | X10: 1.8 | Y10: 街區入口或牌樓／主要街屋與支巷／歷史地標或終點廣場 | Z10: P0｜核心 | AA10: https://www.google.com/maps/search/?api=1&query=%E5%A4%A7%E6%BA%AA%E8%80%81%E8%A1%97%20%E5%A4%A7%E6%BA%AA%E5%8D%80%20%E6%A1%83%E5%9C%92%E5%B8%82 | AB10: https://www.google.com/maps?q=24.885186,121.287470 | AC10: 街區／聚落代表點 | AD10: 新增六章節資料；正式合併 DOR 主表前，請以名稱、行政區及 300 公尺內座標進行去重。 | AE10: 否｜建議新增場域
A11: DOR-TAO-HIS-002 | B11: 桃園市 | C11: 龍潭區 | D11: 老街／歷史街區 | E11: 三坑老街 | F11: Google Maps 街區主地標／主要入口代表點 | G11: 24.843865 | H11: 121.24799 | I11: 4 | J11: ★★★★☆ | K11: 三坑老街具街屋、巷弄、廟宇與地方生活集中，適合用步行解鎖城鎮記憶。 | L11: 三坑老街散步任務｜完成街區主街、支巷與代表地標三段探索，拍攝一處建築細節並完成終點打卡。記錄一個只有步行時才會注意到的細節。 | M11: 公共街區為主；請注意車流、居民生活、商家營業時間及活動管制。 | N11: 200 | O11: B｜Google 場域代表點 | P11: 採觀光署景點資料之 Google 場域代表座標；歷史街區不應直接等同唯一 GPS 任務圓心，需再選定起點、途中節點與終點。 | Q11: 交通部觀光署觀光資訊資料庫（座標地圖以 Google 為主） | R11: https://data.gov.tw/dataset/7777 | S11: 2026-07-13 | T11: 城市散步 | U11: 01｜老街與歷史街區 | V11: 高 | W11: 40–60 分鐘 | X11: 1.8 | Y11: 街區入口或牌樓／主要街屋與支巷／歷史地標或終點廣場 | Z11: P1｜擴充 | AA11: https://www.google.com/maps/search/?api=1&query=%E4%B8%89%E5%9D%91%E8%80%81%E8%A1%97%20%E9%BE%8D%E6%BD%AD%E5%8D%80%20%E6%A1%83%E5%9C%92%E5%B8%82 | AB11: https://www.google.com/maps?q=24.843865,121.247990 | AC11: 街區／聚落代表點 | AD11: 新增六章節資料；正式合併 DOR 主表前，請以名稱、行政區及 300 公尺內座標進行去重。 | AE11: 否｜建議新增場域
A12: DOR-TAO-HIS-003 | B12: 桃園市 | C12: 楊梅區 | D12: 老街／歷史街區 | E12: 富岡老街 | F12: Google Maps 街區主地標／主要入口代表點 | G12: 24.936328 | H12: 121.08243 | I12: 4 | J12: ★★★★☆ | K12: 富岡老街具街屋、巷弄、廟宇與地方生活集中，適合用步行解鎖城鎮記憶。 | L12: 富岡老街散步任務｜完成街區主街、支巷與代表地標三段探索，拍攝一處建築細節並完成終點打卡。以起點、途中與終點三張照片完成探索紀錄。 | M12: 公共街區為主；請注意車流、居民生活、商家營業時間及活動管制。 | N12: 200 | O12: B｜Google 場域代表點 | P12: 採觀光署景點資料之 Google 場域代表座標；歷史街區不應直接等同唯一 GPS 任務圓心，需再選定起點、途中節點與終點。 | Q12: 交通部觀光署觀光資訊資料庫（座標地圖以 Google 為主） | R12: https://data.gov.tw/dataset/7777 | S12: 2026-07-13 | T12: 城市散步 | U12: 01｜老街與歷史街區 | V12: 高 | W12: 40–60 分鐘 | X12: 1.8 | Y12: 街區入口或牌樓／主要街屋與支巷／歷史地標或終點廣場 | Z12: P1｜擴充 | AA12: https://www.google.com/maps/search/?api=1&query=%E5%AF%8C%E5%B2%A1%E8%80%81%E8%A1%97%20%E6%A5%8A%E6%A2%85%E5%8D%80%20%E6%A1%83%E5%9C%92%E5%B8%82 | AB12: https://www.google.com/maps?q=24.936328,121.082430 | AC12: 街區／聚落代表點 | AD12: 新增六章節資料；正式合併 DOR 主表前，請以名稱、行政區及 300 公尺內座標進行去重。 | AE12: 否｜建議新增場域
A13: DOR-HSQ-HIS-001 | B13: 新竹縣 | C13: 北埔鄉 | D13: 老街／歷史街區 | E13: 北埔老街 | F13: Google Maps 街區主地標／主要入口代表點 | G13: 24.699816 | H13: 121.05722 | I13: 5 | J13: ★★★★★ | K13: 北埔老街具街屋、巷弄、廟宇與地方生活集中，適合用步行解鎖城鎮記憶。 | L13: 北埔老街散步任務｜完成街區主街、支巷與代表地標三段探索，拍攝一處建築細節並完成終點打卡。在終點回答一題與場域故事有關的問題。 | M13: 公共街區為主；請注意車流、居民生活、商家營業時間及活動管制。 | N13: 200 | O13: B｜Google 場域代表點 | P13: 採觀光署景點資料之 Google 場域代表座標；歷史街區不應直接等同唯一 GPS 任務圓心，需再選定起點、途中節點與終點。 | Q13: 交通部觀光署觀光資訊資料庫（座標地圖以 Google 為主） | R13: https://data.gov.tw/dataset/7777 | S13: 2026-07-13 | T13: 城市散步 | U13: 01｜老街與歷史街區 | V13: 高 | W13: 40–60 分鐘 | X13: 1.8 | Y13: 街區入口或牌樓／主要街屋與支巷／歷史地標或終點廣場 | Z13: P0｜核心 | AA13: https://www.google.com/maps/search/?api=1&query=%E5%8C%97%E5%9F%94%E8%80%81%E8%A1%97%20%E5%8C%97%E5%9F%94%E9%84%89%20%E6%96%B0%E7%AB%B9%E7%B8%A3 | AB13: https://www.google.com/maps?q=24.699816,121.057220 | AC13: 街區／聚落代表點 | AD13: 新增六章節資料；正式合併 DOR 主表前，請以名稱、行政區及 300 公尺內座標進行去重。 | AE13: 否｜建議新增場域
A14: DOR-HSQ-HIS-002 | B14: 新竹縣 | C14: 湖口鄉 | D14: 老街／歷史街區 | E14: 湖口老街 | F14: Google Maps 街區主地標／主要入口代表點 | G14: 24.876872 | H14: 121.05514 | I14: 4 | J14: ★★★★☆ | K14: 湖口老街具街屋、巷弄、廟宇與地方生活集中，適合用步行解鎖城鎮記憶。 | L14: 湖口老街散步任務｜完成街區主街、支巷與代表地標三段探索，拍攝一處建築細節並完成終點打卡。沿途至少完成三個檢查點。 | M14: 公共街區為主；請注意車流、居民生活、商家營業時間及活動管制。 | N14: 200 | O14: B｜Google 場域代表點 | P14: 採觀光署景點資料之 Google 場域代表座標；歷史街區不應直接等同唯一 GPS 任務圓心，需再選定起點、途中節點與終點。 | Q14: 交通部觀光署觀光資訊資料庫（座標地圖以 Google 為主） | R14: https://data.gov.tw/dataset/7777 | S14: 2026-07-13 | T14: 城市散步 | U14: 01｜老街與歷史街區 | V14: 高 | W14: 40–60 分鐘 | X14: 1.8 | Y14: 街區入口或牌樓／主要街屋與支巷／歷史地標或終點廣場 | Z14: P1｜擴充 | AA14: https://www.google.com/maps/search/?api=1&query=%E6%B9%96%E5%8F%A3%E8%80%81%E8%A1%97%20%E6%B9%96%E5%8F%A3%E9%84%89%20%E6%96%B0%E7%AB%B9%E7%B8%A3 | AB14: https://www.google.com/maps?q=24.876872,121.055140 | AC14: 街區／聚落代表點 | AD14: 新增六章節資料；正式合併 DOR 主表前，請以名稱、行政區及 300 公尺內座標進行去重。 | AE14: 否｜建議新增場域
... A27: DOR-LIE-HIS-001 | B27: 連江縣 | C27: 北竿鄉 | D27: 老街／歷史街區 | E27: 芹壁村 | F27: Google Maps 街區主地標／主要入口代表點 | G27: 26.224782 | H27: 119.98366 | I27: 5 | J27: ★★★★★ | K27: 芹壁村具街屋、巷弄、廟宇與地方生活集中，適合用步行解鎖城鎮記憶。 | L27: 芹壁村散步任務｜完成街區主街、支巷與代表地標三段探索，拍攝一處建築細節並完成終點打卡。記錄一個只有步行時才會注意到的細節。 | M27: 公共街區為主；請注意車流、居民生活、商家營業時間及活動管制。 | N27: 200 | O27: B｜Google 場域代表點 | P27: 採觀光署景點資料之 Google 場域代表座標；歷史街區不應直接等同唯一 GPS 任務圓心，需再選定起點、途中節點與終點。 | Q27: 交通部觀光署觀光資訊資料庫（座標地圖以 Google 為主） | R27: https://data.gov.tw/dataset/7777 | S27: 2026-07-13 | T27: 城市散步 | U27: 01｜老街與歷史街區 | V27: 高 | W27: 40–60 分鐘 | X27: 1.8 | Y27: 街區入口或牌樓／主要街屋與支巷／歷史地標或終點廣場 | Z27: P0｜核心 | AA27: https://www.google.com/maps/search/?api=1&query=%E8%8A%B9%E5%A3%81%E6%9D%91%20%E5%8C%97%E7%AB%BF%E9%84%89%20%E9%80%A3%E6%B1%9F%E7%B8%A3 | AB27: https://www.google.com/maps?q=26.224782,119.983660 | AC27: 街區／聚落代表點 | AD27: 新增六章節資料；正式合併 DOR 主表前，請以名稱、行政區及 300 公尺內座標進行去重。 | AE27: 否｜建議新增場域

Sheet 02鐵道舊鐵路
A1: DOR｜城市探索 02｜鐵道與舊鐵路｜共 25 處
A2: 地點ID | B2: 縣市 | C2: 行政區 | D2: 類型 | E2: 地點名稱 | F2: 打卡點定位 | G2: 緯度（WGS84） | H2: 經度（WGS84） | I2: 星等 | J2: 星等顯示 | K2: 熱門理由 | L2: 建議任務 | M2: 開放性備註 | N2: GPS半徑建議m | O2: 座標可信度 | P2: 座標設定說明 | Q2: 資料來源類型 | R2: 資料來源URL | S2: 整理日期 | T2: 主類別 | U2: 章節 | V2: 散步適合度 | W2: 建議時間 | X2: 建議距離km | Y2: 任務節點建議 | Z2: DOR收錄優先級 | AA2: Google Maps地標搜尋 | AB2: Google Maps座標檢視 | AC2: 座標場域類型 | AD2: 去重備註 | AE2: 與既有公園資料關係
A3: DOR-NTP-RAIL-001 | B3: 新北市 | C3: 貢寮區 | D3: 鐵道／舊鐵路 | E3: 舊草嶺隧道 | F3: 車站、隧道口或鐵道遺構主地標 | G3: 25.003945 | H3: 121.95834 | I3: 5 | J3: ★★★★★ | K3: 舊草嶺隧道具鐵道天然具備起點、路線與終點，可串聯站房、月台及產業記憶。 | L3: 舊草嶺隧道散步任務｜由站房或遺構起點出發，尋找兩種鐵道設施並完成一段舊線巡遊。記錄一個只有步行時才會注意到的細節。 | M3: 須遵守鐵路與園區管制；禁止進入營運軌道，隧道與山線請確認開放及照明。 | N3: 120 | O3: A｜觀光署 Google 基準 POI | P3: 採觀光署景點資料之 Google 基準 POI 座標；正式上線前仍應確認圖釘名稱、入口與實際步行動線。 | Q3: 交通部觀光署觀光資訊資料庫（座標地圖以 Google 為主） | R3: https://data.gov.tw/dataset/7777 | S3: 2026-07-13 | T3: 城市散步 | U3: 02｜鐵道與舊鐵路 | V3: 中高 | W3: 45–75 分鐘 | X3: 2.5 | Y3: 站房或隧道口／月台、鐵橋或鐵道設施／終點聚落或產業地標 | Z3: P0｜核心 | AA3: https://www.google.com/maps/search/?api=1&query=%E8%88%8A%E8%8D%89%E5%B6%BA%E9%9A%A7%E9%81%93%20%E8%B2%A2%E5%AF%AE%E5%8D%80%20%E6%96%B0%E5%8C%97%E5%B8%82 | AB3: https://www.google.com/maps?q=25.003945,121.958340 | AC3: 車站／鐵道遺構 POI | AD3: 新增六章節資料；正式合併 DOR 主表前，請以名稱、行政區及 300 公尺內座標進行去重。 | AE3: 否｜建議新增場域
A4: DOR-NTP-RAIL-002 | B4: 新北市 | C4: 平溪區 | D4: 鐵道／舊鐵路 | E4: 十分風景特定區 | F4: 車站、隧道口或鐵道遺構主地標 | G4: 25.047389 | H4: 121.78285 | I4: 5 | J4: ★★★★★ | K4: 十分風景特定區具鐵道天然具備起點、路線與終點，可串聯站房、月台及產業記憶。 | L4: 十分風景特定區散步任務｜由站房或遺構起點出發，尋找兩種鐵道設施並完成一段舊線巡遊。以起點、途中與終點三張照片完成探索紀錄。 | M4: 須遵守鐵路與園區管制；禁止進入營運軌道，隧道與山線請確認開放及照明。 | N4: 120 | O4: A｜觀光署 Google 基準 POI | P4: 採觀光署景點資料之 Google 基準 POI 座標；正式上線前仍應確認圖釘名稱、入口與實際步行動線。 | Q4: 交通部觀光署觀光資訊資料庫（座標地圖以 Google 為主） | R4: https://data.gov.tw/dataset/7777 | S4: 2026-07-13 | T4: 城市散步 | U4: 02｜鐵道與舊鐵路 | V4: 中高 | W4: 45–75 分鐘 | X4: 2.5 | Y4: 站房或隧道口／月台、鐵橋或鐵道設施／終點聚落或產業地標 | Z4: P0｜核心 | AA4: https://www.google.com/maps/search/?api=1&query=%E5%8D%81%E5%88%86%E9%A2%A8%E6%99%AF%E7%89%B9%E5%AE%9A%E5%8D%80%20%E5%B9%B3%E6%BA%AA%E5%8D%80%20%E6%96%B0%E5%8C%97%E5%B8%82 | AB4: https://www.google.com/maps?q=25.047389,121.782850 | AC4: 車站／鐵道遺構 POI | AD4: 新增六章節資料；正式合併 DOR 主表前，請以名稱、行政區及 300 公尺內座標進行去重。 | AE4: 否｜建議新增場域
A5: DOR-NTP-RAIL-003 | B5: 新北市 | C5: 平溪區 | D5: 鐵道／舊鐵路 | E5: 平溪鐵道街區 | F5: 車站、隧道口或鐵道遺構主地標 | G5: 25.026689 | H5: 121.73819 | I5: 4 | J5: ★★★★☆ | K5: 平溪鐵道街區具鐵道天然具備起點、路線與終點，可串聯站房、月台及產業記憶。 | L5: 平溪鐵道街區散步任務｜由站房或遺構起點出發，尋找兩種鐵道設施並完成一段舊線巡遊。在終點回答一題與場域故事有關的問題。 | M5: 須遵守鐵路與園區管制；禁止進入營運軌道，隧道與山線請確認開放及照明。 | N5: 200 | O5: B｜Google 場域代表點 | P5: 採觀光署景點資料之 Google 場域代表座標；街區、港區或線性路線不應直接等同唯一 GPS 任務圓心，需再選定任務節點。 | Q5: 交通部觀光署觀光資訊資料庫（座標地圖以 Google 為主） | R5: https://data.gov.tw/dataset/7777 | S5: 2026-07-13 | T5: 城市散步 | U5: 02｜鐵道與舊鐵路 | V5: 中高 | W5: 45–75 分鐘 | X5: 2.5 | Y5: 站房或隧道口／月台、鐵橋或鐵道設施／終點聚落或產業地標 | Z5: P1｜擴充 | AA5: https://www.google.com/maps/search/?api=1&query=%E5%B9%B3%E6%BA%AA%E9%90%B5%E9%81%93%E8%A1%97%E5%8D%80%20%E5%B9%B3%E6%BA%AA%E5%8D%80%20%E6%96%B0%E5%8C%97%E5%B8%82 | AB5: https://www.google.com/maps?q=25.026689,121.738190 | AC5: 鐵道路線／街區代表點 | AD5: 新增六章節資料；正式合併 DOR 主表前，請以名稱、行政區及 300 公尺內座標進行去重。 | AE5: 否｜建議新增場域
A6: DOR-NTP-RAIL-004 | B6: 新北市 | C6: 烏來區 | D6: 鐵道／舊鐵路 | E6: 烏來台車與老街 | F6: 車站、隧道口或鐵道遺構主地標 | G6: 24.864935 | H6: 121.55198 | I6: 4 | J6: ★★★★☆ | K6: 烏來台車與老街具鐵道天然具備起點、路線與終點，可串聯站房、月台及產業記憶。 | L6: 烏來台車與老街散步任務｜由站房或遺構起點出發，尋找兩種鐵道設施並完成一段舊線巡遊。沿途至少完成三個檢查點。 | M6: 須遵守鐵路與園區管制；禁止進入營運軌道，隧道與山線請確認開放及照明。 | N6: 200 | O6: B｜Google 場域代表點 | P6: 採觀光署景點資料之 Google 場域代表座標；街區、港區或線性路線不應直接等同唯一 GPS 任務圓心，需再選定任務節點。 | Q6: 交通部觀光署觀光資訊資料庫（座標地圖以 Google 為主） | R6: https://data.gov.tw/dataset/7777 | S6: 2026-07-13 | T6: 城市散步 | U6: 02｜鐵道與舊鐵路 | V6: 中高 | W6: 45–75 分鐘 | X6: 2.5 | Y6: 站房或隧道口／月台、鐵橋或鐵道設施／終點聚落或產業地標 | Z6: P1｜擴充 | AA6: https://www.google.com/maps/search/?api=1&query=%E7%83%8F%E4%BE%86%E5%8F%B0%E8%BB%8A%E8%88%87%E8%80%81%E8%A1%97%20%E7%83%8F%E4%BE%86%E5%8D%80%20%E6%96%B0%E5%8C%97%E5%B8%82 | AB6: https://www.google.com/maps?q=24.864935,121.551980 | AC6: 鐵道路線／街區代表點 | AD6: 新增六章節資料；正式合併 DOR 主表前，請以名稱、行政區及 300 公尺內座標進行去重。 | AE6: 否｜建議新增場域
A7: DOR-HSQ-RAIL-001 | B7: 新竹縣 | C7: 橫山鄉 | D7: 鐵道／舊鐵路 | E7: 內灣小鎮 | F7: 車站、隧道口或鐵道遺構主地標 | G7: 24.705431 | H7: 121.18247 | I7: 5 | J7: ★★★★★ | K7: 內灣小鎮具鐵道天然具備起點、路線與終點，可串聯站房、月台及產業記憶。 | L7: 內灣小鎮散步任務｜由站房或遺構起點出發，尋找兩種鐵道設施並完成一段舊線巡遊。記錄一個只有步行時才會注意到的細節。 | M7: 須遵守鐵路與園區管制；禁止進入營運軌道，隧道與山線請確認開放及照明。 | N7: 120 | O7: A｜觀光署 Google 基準 POI | P7: 採觀光署景點資料之 Google 基準 POI 座標；正式上線前仍應確認圖釘名稱、入口與實際步行動線。 | Q7: 交通部觀光署觀光資訊資料庫（座標地圖以 Google 為主） | R7: https://data.gov.tw/dataset/7777 | S7: 2026-07-13 | T7: 城市散步 | U7: 02｜鐵道與舊鐵路 | V7: 中高 | W7: 45–75 分鐘 | X7: 2.5 | Y7: 站房或隧道口／月台、鐵橋或鐵道設施／終點聚落或產業地標 | Z7: P0｜核心 | AA7: https://www.google.com/maps/search/?api=1&query=%E5%85%A7%E7%81%A3%E5%B0%8F%E9%8E%AE%20%E6%A9%AB%E5%B1%B1%E9%84%89%20%E6%96%B0%E7%AB%B9%E7%B8%A3 | AB7: https://www.google.com/maps?q=24.705431,121.182470 | AC7: 車站／鐵道遺構 POI | AD7: 新增六章節資料；正式合併 DOR 主表前，請以名稱、行政區及 300 公尺內座標進行去重。 | AE7: 否｜建議新增場域
A8: DOR-MIA-RAIL-001 | B8: 苗栗縣 | C8: 三義鄉 | D8: 鐵道／舊鐵路 | E8: 勝興車站 | F8: 車站、隧道口或鐵道遺構主地標 | G8: 24.38823 | H8: 120.78205 | I8: 5 | J8: ★★★★★ | K8: 勝興車站具鐵道天然具備起點、路線與終點，可串聯站房、月台及產業記憶。 | L8: 勝興車站散步任務｜由站房或遺構起點出發，尋找兩種鐵道設施並完成一段舊線巡遊。以起點、途中與終點三張照片完成探索紀錄。 | M8: 須遵守鐵路與園區管制；禁止進入營運軌道，隧道與山線請確認開放及照明。 | N8: 120 | O8: A｜觀光署 Google 基準 POI | P8: 採觀光署景點資料之 Google 基準 POI 座標；正式上線前仍應確認圖釘名稱、入口與實際步行動線。 | Q8: 交通部觀光署觀光資訊資料庫（座標地圖以 Google 為主） | R8: https://data.gov.tw/dataset/7777 | S8: 2026-07-13 | T8: 城市散步 | U8: 02｜鐵道與舊鐵路 | V8: 中高 | W8: 45–75 分鐘 | X8: 2.5 | Y8: 站房或隧道口／月台、鐵橋或鐵道設施／終點聚落或產業地標 | Z8: P0｜核心 | AA8: https://www.google.com/maps/search/?api=1&query=%E5%8B%9D%E8%88%88%E8%BB%8A%E7%AB%99%20%E4%B8%89%E7%BE%A9%E9%84%89%20%E8%8B%97%E6%A0%97%E7%B8%A3 | AB8: https://www.google.com/maps?q=24.388230,120.782050 | AC8: 車站／鐵道遺構 POI | AD8: 新增六章節資料；正式合併 DOR 主表前，請以名稱、行政區及 300 公尺內座標進行去重。 | AE8: 否｜建議新增場域
A9: DOR-MIA-RAIL-002 | B9: 苗栗縣 | C9: 三義鄉 | D9: 鐵道／舊鐵路 | E9: 龍騰斷橋 | F9: 車站、隧道口或鐵道遺構主地標 | G9: 24.358435 | H9: 120.77384 | I9: 5 | J9: ★★★★★ | K9: 龍騰斷橋具鐵道天然具備起點、路線與終點，可串聯站房、月台及產業記憶。 | L9: 龍騰斷橋散步任務｜由站房或遺構起點出發，尋找兩種鐵道設施並完成一段舊線巡遊。在終點回答一題與場域故事有關的問題。 | M9: 須遵守鐵路與園區管制；禁止進入營運軌道，隧道與山線請確認開放及照明。 | N9: 120 | O9: A｜觀光署 Google 基準 POI | P9: 採觀光署景點資料之 Google 基準 POI 座標；正式上線前仍應確認圖釘名稱、入口與實際步行動線。 | Q9: 交通部觀光署觀光資訊資料庫（座標地圖以 Google 為主） | R9: https://data.gov.tw/dataset/7777 | S9: 2026-07-13 | T9: 城市散步 | U9: 02｜鐵道與舊鐵路 | V9: 中高 | W9: 45–75 分鐘 | X9: 2.5 | Y9: 站房或隧道口／月台、鐵橋或鐵道設施／終點聚落或產業地標 | Z9: P0｜核心 | AA9: https://www.google.com/maps/search/?api=1&query=%E9%BE%8D%E9%A8%B0%E6%96%B7%E6%A9%8B%20%E4%B8%89%E7%BE%A9%E9%84%89%20%E8%8B%97%E6%A0%97%E7%B8%A3 | AB9: https://www.google.com/maps?q=24.358435,120.773840 | AC9: 車站／鐵道遺構 POI | AD9: 新增六章節資料；正式合併 DOR 主表前，請以名稱、行政區及 300 公尺內座標進行去重。 | AE9: 否｜建議新增場域
A10: DOR-MIA-RAIL-003 | B10: 苗栗縣 | C10: 苗栗市 | D10: 鐵道／舊鐵路 | E10: 功維敘隧道 | F10: 車站、隧道口或鐵道遺構主地標 | G10: 24.554356 | H10: 120.81096 | I10: 4 | J10: ★★★★☆ | K10: 功維敘隧道具鐵道天然具備起點、路線與終點，可串聯站房、月台及產業記憶。 | L10: 功維敘隧道散步任務｜由站房或遺構起點出發，尋找兩種鐵道設施並完成一段舊線巡遊。沿途至少完成三個檢查點。 | M10: 須遵守鐵路與園區管制；禁止進入營運軌道，隧道與山線請確認開放及照明。 | N10: 120 | O10: A｜觀光署 Google 基準 POI | P10: 採觀光署景點資料之 Google 基準 POI 座標；正式上線前仍應確認圖釘名稱、入口與實際步行動線。 | Q10: 交通部觀光署觀光資訊資料庫（座標地圖以 Google 為主） | R10: https://data.gov.tw/dataset/7777 | S10: 2026-07-13 | T10: 城市散步 | U10: 02｜鐵道與舊鐵路 | V10: 中高 | W10: 45–75 分鐘 | X10: 2.5 | Y10: 站房或隧道口／月台、鐵橋或鐵道設施／終點聚落或產業地標 | Z10: P1｜擴充 | AA10: https://www.google.com/maps/search/?api=1&query=%E5%8A%9F%E7%B6%AD%E6%95%98%E9%9A%A7%E9%81%93%20%E8%8B%97%E6%A0%97%E5%B8%82%20%E8%8B%97%E6%A0%97%E7%B8%A3 | AB10: https://www.google.com/maps?q=24.554356,120.810960 | AC10: 車站／鐵道遺構 POI | AD10: 新增六章節資料；正式合併 DOR 主表前，請以名稱、行政區及 300 公尺內座標進行去重。 | AE10: 否｜建議新增場域
A11: DOR-TXG-RAIL-001 | B11: 臺中市 | C11: 石岡區 | D11: 鐵道／舊鐵路 | E11: 東豐自行車綠廊 | F11: 車站、隧道口或鐵道遺構主地標 | G11: 24.276023 | H11: 120.77879 | I11: 4 | J11: ★★★★☆ | K11: 東豐自行車綠廊具鐵道天然具備起點、路線與終點，可串聯站房、月台及產業記憶。 | L11: 東豐自行車綠廊散步任務｜由站房或遺構起點出發，尋找兩種鐵道設施並完成一段舊線巡遊。記錄一個只有步行時才會注意到的細節。 | M11: 須遵守鐵路與園區管制；禁止進入營運軌道，隧道與山線請確認開放及照明。 | N11: 200 | O11: B｜Google 場域代表點 | P11: 採觀光署景點資料之 Google 場域代表座標；街區、港區或線性路線不應直接等同唯一 GPS 任務圓心，需再選定任務節點。 | Q11: 交通部觀光署觀光資訊資料庫（座標地圖以 Google 為主） | R11: https://data.gov.tw/dataset/7777 | S11: 2026-07-13 | T11: 城市散步 | U11: 02｜鐵道與舊鐵路 | V11: 中高 | W11: 45–75 分鐘 | X11: 2.5 | Y11: 站房或隧道口／月台、鐵橋或鐵道設施／終點聚落或產業地標 | Z11: P1｜擴充 | AA11: https://www.google.com/maps/search/?api=1&query=%E6%9D%B1%E8%B1%90%E8%87%AA%E8%A1%8C%E8%BB%8A%E7%B6%A0%E5%BB%8A%20%E7%9F%B3%E5%B2%A1%E5%8D%80%20%E8%87%BA%E4%B8%AD%E5%B8%82 | AB11: https://www.google.com/maps?q=24.276023,120.778790 | AC11: 鐵道路線／街區代表點 | AD11: 新增六章節資料；正式合併 DOR 主表前，請以名稱、行政區及 300 公尺內座標進行去重。 | AE11: 否｜建議新增場域
A12: DOR-TXG-RAIL-002 | B12: 臺中市 | C12: 東勢區 | D12: 鐵道／舊鐵路 | E12: 東勢林業文化園區 | F12: 車站、隧道口或鐵道遺構主地標 | G12: 24.243787 | H12: 120.83365 | I12: 4 | J12: ★★★★☆ | K12: 東勢林業文化園區具鐵道天然具備起點、路線與終點，可串聯站房、月台及產業記憶。 | L12: 東勢林業文化園區散步任務｜由站房或遺構起點出發，尋找兩種鐵道設施並完成一段舊線巡遊。以起點、途中與終點三張照片完成探索紀錄。 | M12: 須遵守鐵路與園區管制；禁止進入營運軌道，隧道與山線請確認開放及照明。 | N12: 120 | O12: A｜觀光署 Google 基準 POI | P12: 採觀光署景點資料之 Google 基準 POI 座標；正式上線前仍應確認圖釘名稱、入口與實際步行動線。 | Q12: 交通部觀光署觀光資訊資料庫（座標地圖以 Google 為主） | R12: https://data.gov.tw/dataset/7777 | S12: 2026-07-13 | T12: 城市散步 | U12: 02｜鐵道與舊鐵路 | V12: 中高 | W12: 45–75 分鐘 | X12: 2.5 | Y12: 站房或隧道口／月台、鐵橋或鐵道設施／終點聚落或產業地標 | Z12: P1｜擴充 | AA12: https://www.google.com/maps/search/?api=1&query=%E6%9D%B1%E5%8B%A2%E6%9E%97%E6%A5%AD%E6%96%87%E5%8C%96%E5%9C%92%E5%8D%80%20%E6%9D%B1%E5%8B%A2%E5%8D%80%20%E8%87%BA%E4%B8%AD%E5%B8%82 | AB12: https://www.google.com/maps?q=24.243787,120.833650 | AC12: 車站／鐵道遺構 POI | AD12: 新增六章節資料；正式合併 DOR 主表前，請以名稱、行政區及 300 公尺內座標進行去重。 | AE12: 否｜建議新增場域
A13: DOR-CHA-RAIL-001 | B13: 彰化縣 | C13: 彰化市 | D13: 鐵道／舊鐵路 | E13: 扇形車庫 | F13: 車站、隧道口或鐵道遺構主地標 | G13: 24.085948 | H13: 120.54017 | I13: 5 | J13: ★★★★★ | K13: 扇形車庫具鐵道天然具備起點、路線與終點，可串聯站房、月台及產業記憶。 | L13: 扇形車庫散步任務｜由站房或遺構起點出發，尋找兩種鐵道設施並完成一段舊線巡遊。在終點回答一題與場域故事有關的問題。 | M13: 須遵守鐵路與園區管制；禁止進入營運軌道，隧道與山線請確認開放及照明。 | N13: 120 | O13: A｜觀光署 Google 基準 POI | P13: 採觀光署景點資料之 Google 基準 POI 座標；正式上線前仍應確認圖釘名稱、入口與實際步行動線。 | Q13: 交通部觀光署觀光資訊資料庫（座標地圖以 Google 為主） | R13: https://data.gov.tw/dataset/7777 | S13: 2026-07-13 | T13: 城市散步 | U13: 02｜鐵道與舊鐵路 | V13: 中高 | W13: 45–75 分鐘 | X13: 2.5 | Y13: 站房或隧道口／月台、鐵橋或鐵道設施／終點聚落或產業地標 | Z13: P0｜核心 | AA13: https://www.google.com/maps/search/?api=1&query=%E6%89%87%E5%BD%A2%E8%BB%8A%E5%BA%AB%20%E5%BD%B0%E5%8C%96%E5%B8%82%20%E5%BD%B0%E5%8C%96%E7%B8%A3 | AB13: https://www.google.com/maps?q=24.085948,120.540170 | AC13: 車站／鐵道遺構 POI | AD13: 新增六章節資料；正式合併 DOR 主表前，請以名稱、行政區及 300 公尺內座標進行去重。 | AE13: 否｜建議新增場域
A14: DOR-CHA-RAIL-002 | B14: 彰化縣 | C14: 社頭鄉 | D14: 鐵道／舊鐵路 | E14: 福井鐵道文物館 | F14: 車站、隧道口或鐵道遺構主地標 | G14: 23.896964 | H14: 120.58521 | I14: 4 | J14: ★★★★☆ | K14: 福井鐵道文物館具鐵道天然具備起點、路線與終點，可串聯站房、月台及產業記憶。 | L14: 福井鐵道文物館散步任務｜由站房或遺構起點出發，尋找兩種鐵道設施並完成一段舊線巡遊。沿途至少完成三個檢查點。 | M14: 須遵守鐵路與園區管制；禁止進入營運軌道，隧道與山線請確認開放及照明。 | N14: 200 | O14: B｜Google 場域代表點 | P14: 採觀光署景點資料之 Google 場域代表座標；街區、港區或線性路線不應直接等同唯一 GPS 任務圓心，需再選定任務節點。 | Q14: 交通部觀光署觀光資訊資料庫（座標地圖以 Google 為主） | R14: https://data.gov.tw/dataset/7777 | S14: 2026-07-13 | T14: 城市散步 | U14: 02｜鐵道與舊鐵路 | V14: 中高 | W14: 45–75 分鐘 | X14: 2.5 | Y14: 站房或隧道口／月台、鐵橋或鐵道設施／終點聚落或產業地標 | Z14: P1｜擴充 | AA14: https://www.google.com/maps/search/?api=1&query=%E7%A6%8F%E4%BA%95%E9%90%B5%E9%81%93%E6%96%87%E7%89%A9%E9%A4%A8%20%E7%A4%BE%E9%A0%AD%E9%84%89%20%E5%BD%B0%E5%8C%96%E7%B8%A3 | AB14: https://www.google.com/maps?q=23.896964,120.585210 | AC14: 鐵道路線／街區代表點 | AD14: 新增六章節資料；正式合併 DOR 主表前，請以名稱、行政區及 300 公尺內座標進行去重。 | AE14: 否｜建議新增場域
